Workbook

Sheet Cover
A1: The Chocolate Shop- Fall 2024
A3: Project | B3: This is a set of financial statement prepared for the owner of Chocolate Shop to help with forecasting, budgeting, and overall financial analysis of a start-up business in chocolate manufacturing and retaining.
A5: Contents
A6: Cover Page | B6: This page
A7: CFF | B7: Cash Flow Statement
A8: IS | B8: Proforma Income Statement(s) Including Comparisons to Industry Performance Data.
A9: BS | B9: Proforma Balance Sheet(s)
A10: Startup | B10: Startup expenses are entered here. Includes a Statement of Cash and Startup Income Statement and Balance Sheet.
A11: Sales + Inventory+Cost | B11: Sales Projections, Inventory and Cost of goods sold
A12: Assets | B12: Capital Purchases and Depreciation
A13: HR Exp | B13: Owner Drawings and Employee Expenses
A14: Financing | B14: Financing including investments, loans and lines of Credit
A15: Other Exp | B15: Other expenses including location, marketing, delivery, etc.
A16: NAICS % | B16: 2022 Industry Performance Data Sheet Unincorporated %
A17: NAICS $ | B17: 2022 Industry Performance Data Sheet Unincorporated $
A19: LEGEND
A20: User input cell | B20: Fields that can be changed and reflected in the calculations
A21: Calculated Cells | B21: Theses cells are calculated and should not be changed
A22: Check calculations | B22: Calculations used to validate the spreadsheet. This can ignored and should note printed.
A23: Memo | B23: Memo field linked to original source
A24: Instructions | B24: Instructions are included throughout the template in the boxes show in this colour
A26: Statement of Proof of Work | B26: "I have read and understand the rules regarding plagiarism/copying/cheating. I may have discussed with others but at NO time did I allow my work to be copied nor did I copy rom another student (past or present). I understand I may receive a zero on this assignment (one or both parts) and receive disciplinary action of turning in word that is not solely my own."
B27: Signed by: Miraj Sangani

Sheet CFF
B1: The Chocolate Shop
B2: Proforma Cash Flow Statement
B3: January 2025 To December 2025
C5: 1 | D5: 2 | E5: 3 | F5: 4 | G5: 5 | H5: 6 | I5: 7 | J5: 8 | K5: 9 | L5: 10 | M5: 11 | N5: 12
A6: Notes | B6: Inflows | C6: 45658 | D6: 45689 | E6: 45717 | F6: 45748 | G6: 45778 | H6: 45809 | I6: 45839 | J6: 45870 | K6: 45901 | L6: 45931 | M6: 45962 | N6: 45992 | O6: Year 1 Total
A7: Sales+Inv | B7: Factory Sales- Cash | C7: ='Sales+Inv+Cost'!B19 -> 819 | D7: ='Sales+Inv+Cost'!C19 -> 1638 | E7: ='Sales+Inv+Cost'!D19 -> 1638 | F7: ='Sales+Inv+Cost'!E19 -> 2047.5 | G7: ='Sales+Inv+Cost'!F19 -> 819 | H7: ='Sales+Inv+Cost'!G19 -> 2047.5 | I7: ='Sales+Inv+Cost'!H19 -> 3276 | J7: ='Sales+Inv+Cost'!I19 -> 3276 | ... N7: ='Sales+Inv+Cost'!M19 -> 9009 | O7: =SUM(C7:N7) -> 40950
A8: Sales+Inv | B8: Factory Sales- Cr. Card | C8: ='Sales+Inv+Cost'!B20 -> 351 | D8: ='Sales+Inv+Cost'!C20 -> 702 | E8: ='Sales+Inv+Cost'!D20 -> 702 | F8: ='Sales+Inv+Cost'!E20 -> 877.5 | G8: ='Sales+Inv+Cost'!F20 -> 351 | H8: ='Sales+Inv+Cost'!G20 -> 877.5 | I8: ='Sales+Inv+Cost'!H20 -> 1404 | J8: ='Sales+Inv+Cost'!I20 -> 1404 | ... N8: ='Sales+Inv+Cost'!M20 -> 3861 | O8: =SUM(C8:N8) -> 17550
B9: Total Factory Sales | C9: ='Sales+Inv+Cost'!B18 -> 1170 | D9: ='Sales+Inv+Cost'!C18 -> 2340 | E9: ='Sales+Inv+Cost'!D18 -> 2340 | F9: ='Sales+Inv+Cost'!E18 -> 2925 | G9: ='Sales+Inv+Cost'!F18 -> 1170 | H9: ='Sales+Inv+Cost'!G18 -> 2925 | I9: ='Sales+Inv+Cost'!H18 -> 4680 | J9: ='Sales+Inv+Cost'!I18 -> 4680 | ... N9: ='Sales+Inv+Cost'!M18 -> 12870 | O9: =SUM(C9:N9) -> 58500
A10: Sales+Inv | B10: Tradeshow sales - Cash | C10: ='Sales+Inv+Cost'!B26 -> 0 | D10: ='Sales+Inv+Cost'!C26 -> 1092 | E10: ='Sales+Inv+Cost'!D26 -> 624 | F10: ='Sales+Inv+Cost'!E26 -> 780 | G10: ='Sales+Inv+Cost'!F26 -> 0 | H10: ='Sales+Inv+Cost'!G26 -> 0 | I10: ='Sales+Inv+Cost'!H26 -> 780 | J10: ='Sales+Inv+Cost'!I26 -> 1560 | ... N10: ='Sales+Inv+Cost'!M26 -> 1872 | O10: =SUM(C10:N10) -> 15600
A11: Sales+Inv | B11: Tradeshow sales - Cr. Card | C11: ='Sales+Inv+Cost'!B27 -> 0 | D11: ='Sales+Inv+Cost'!C27 -> 9828 | E11: ='Sales+Inv+Cost'!D27 -> 5616 | F11: ='Sales+Inv+Cost'!E27 -> 7020 | G11: ='Sales+Inv+Cost'!F27 -> 0 | H11: ='Sales+Inv+Cost'!G27 -> 0 | I11: ='Sales+Inv+Cost'!H27 -> 7020 | J11: ='Sales+Inv+Cost'!I27 -> 14040 | ... N11: ='Sales+Inv+Cost'!M27 -> 16848 | O11: =SUM(C11:N11) -> 140400
B12: Total Tradeshow Sales | C12: ='Sales+Inv+Cost'!B25 -> 0 | D12: ='Sales+Inv+Cost'!C25 -> 10920 | E12: ='Sales+Inv+Cost'!D25 -> 6240 | F12: ='Sales+Inv+Cost'!E25 -> 7800 | G12: ='Sales+Inv+Cost'!F25 -> 0 | H12: ='Sales+Inv+Cost'!G25 -> 0 | I12: ='Sales+Inv+Cost'!H25 -> 7800 | J12: ='Sales+Inv+Cost'!I25 -> 15600 | ... N12: ='Sales+Inv+Cost'!M25 -> 18720 | O12: =SUM(C12:N12) -> 156000
A13: Sales+Inv | B13: Preorder Sales- Cr. Card | C13: ='Sales+Inv+Cost'!B33 -> 0 | D13: ='Sales+Inv+Cost'!C33 -> 5746 | E13: ='Sales+Inv+Cost'!D33 -> 4309.5 | F13: ='Sales+Inv+Cost'!E33 -> 3591.25 | G13: ='Sales+Inv+Cost'!F33 -> 2873 | H13: ='Sales+Inv+Cost'!G33 -> 2154.75 | I13: ='Sales+Inv+Cost'!H33 -> 2154.75 | J13: ='Sales+Inv+Cost'!I33 -> 1436.5 | ... N13: ='Sales+Inv+Cost'!M33 -> 17956.25 | O13: =SUM(C13:N13) -> 71825
A14: Sales+Inv | B14: Preorder Sales- Net 30 (Collect 30 days later) | C14: ='Sales+Inv+Cost'!B38 -> 0 | D14: ='Sales+Inv+Cost'!C38 -> 0 | E14: ='Sales+Inv+Cost'!D38 -> 3094 | F14: ='Sales+Inv+Cost'!E38 -> 2320.5 | G14: ='Sales+Inv+Cost'!F38 -> 1933.75 | H14: ='Sales+Inv+Cost'!G38 -> 1547 | I14: ='Sales+Inv+Cost'!H38 -> 1160.25 | J14: ='Sales+Inv+Cost'!I38 -> 1160.25 | ... N14: ='Sales+Inv+Cost'!M38 -> 7348.25 | O14: =SUM(C14:N14) -> 29006.25
B15: Total Preorder Sales | C15: =SUM(C13:C14) -> 0 | D15: =SUM(D13:D14) -> 5746 | E15: =SUM(E13:E14) -> 7403.5 | F15: =SUM(F13:F14) -> 5911.75 | G15: =SUM(G13:G14) -> 4806.75 | H15: =SUM(H13:H14) -> 3701.75 | I15: =SUM(I13:I14) -> 3315 | J15: =SUM(J13:J14) -> 2596.75 | ... N15: =SUM(N13:N14) -> 25304.5 | O15: =SUM(C15:N15) -> 100831.25
B16: Total Sales | C16: =C9+C12+C15 -> 1170 | D16: =D9+D12+D15 -> 19006 | E16: =E9+E12+E15 -> 15983.5 | F16: =F9+F12+F15 -> 16636.75 | G16: =G9+G12+G15 -> 5976.75 | H16: =H9+H12+H15 -> 6626.75 | I16: =I9+I12+I15 -> 15795 | J16: =J9+J12+J15 -> 22876.75 | ... N16: =N9+N12+N15 -> 56894.5 | O16: =SUM(C16:N16) -> 315331.25
A17: Startup | B17: Owner's Investment | C17: =Startup!B33 -> 60000 | D17: 0 | E17: 0 | F17: 0 | G17: 0 | H17: 0 | I17: 0 | J17: 0 | K17: 0 | L17: 0 | M17: 0 | N17: 0 | O17: =SUM(C17:N17) -> 60000
A18: Financing | B18: Loan | C18: =Financing!B16 -> 35000 | D18: 0 | E18: 0 | F18: 0 | G18: 0 | H18: 0 | I18: 0 | J18: 0 | K18: 0 | L18: 0 | M18: 0 | N18: 0 | O18: =SUM(C18:N18) -> 35000
B19: Total Inflows | C19: =C16+C17+C18 -> 96170 | D19: =D16+D17+D18 -> 19006 | E19: =E16+E17+E18 -> 15983.5 | F19: =F16+F17+F18 -> 16636.75 | G19: =G16+G17+G18 -> 5976.75 | H19: =H16+H17+H18 -> 6626.75 | I19: =I16+I17+I18 -> 15795 | J19: =J16+J17+J18 -> 22876.75 | ... O19: =O16+O17+O18 -> 410331.25
B21: Outflows
A22: Startup | B22: Startup Expenses | C22: =Startup!B23 -> 11910 | O22: =SUM(C22:N22) -> 11910
A23: HRExp | B23: Wages and Benefits (total) | C23: ='HR Exp'!E24 -> 0 | D23: ='HR Exp'!F24 -> 0 | E23: ='HR Exp'!G24 -> 4782.4 | F23: ='HR Exp'!H24 -> 5044.36 | G23: ='HR Exp'!I24 -> 4782.4 | H23: ='HR Exp'!J24 -> 4782.4 | I23: ='HR Exp'!K24 -> 5328.15 | J23: ='HR Exp'!L24 -> 5873.9 | ... N23: ='HR Exp'!P24 -> 7838.6 | O23: =SUM(C23:N23) -> 66095.71
A24: OtherExp | B24: Repairs and Maintenance | C24: ='Other Exp'!$F$3 -> 325 | D24: ='Other Exp'!$F$3 -> 325 | E24: ='Other Exp'!$F$3 -> 325 | F24: ='Other Exp'!$F$3 -> 325 | G24: ='Other Exp'!$F$3 -> 325 | H24: ='Other Exp'!$F$3 -> 325 | I24: ='Other Exp'!$F$3 -> 325 | J24: ='Other Exp'!$F$3 -> 325 | ... N24: ='Other Exp'!$F$3 -> 325 | O24: =SUM(C24:N24) -> 3900
A25: OtherExp | B25: Utilities and Telephone | C25: ='Other Exp'!$F$8 -> 350 | D25: ='Other Exp'!$F$8 -> 350 | E25: ='Other Exp'!$F$8 -> 350 | F25: ='Other Exp'!$F$8 -> 350 | G25: ='Other Exp'!$F$8 -> 350 | H25: ='Other Exp'!$F$8 -> 350 | I25: ='Other Exp'!$F$8 -> 350 | J25: ='Other Exp'!$F$8 -> 350 | ... N25: ='Other Exp'!$F$8 -> 350 | O25: =SUM(C25:N25) -> 4200
A26: OtherExp | B26: Lease and Location Expense | C26: ='Other Exp'!$F$15 -> 858.85417 | D26: ='Other Exp'!$F$15 -> 858.85417 | E26: ='Other Exp'!$F$15 -> 858.85417 | F26: ='Other Exp'!$F$15 -> 858.85417 | G26: ='Other Exp'!$F$15 -> 858.85417 | H26: ='Other Exp'!$F$15 -> 858.85417 | I26: ='Other Exp'!$F$15 -> 858.85417 | J26: ='Other Exp'!$F$15 -> 858.85417 | ... N26: ='Other Exp'!$F$15 -> 858.85417 | O26: =SUM(C26:N26) -> 10306.25
A27: OtherExp | B27: Professional Fees and Memberships | C27: ='Other Exp'!F21 -> 1300 | D27: ='Other Exp'!G21 -> 1300 | E27: ='Other Exp'!H21 -> 1300 | F27: ='Other Exp'!I21 -> 1300 | G27: ='Other Exp'!J21 -> 1750 | H27: ='Other Exp'!K21 -> 0 | I27: ='Other Exp'!L21 -> 0 | J27: ='Other Exp'!M21 -> 0 | ... N27: ='Other Exp'!Q21 -> 0 | O27: =SUM(C27:N27) -> 7600
A28: OtherExp | B28: Marketing | C28: ='Other Exp'!F26 -> 0 | D28: ='Other Exp'!G26 -> 0 | E28: ='Other Exp'!H26 -> 375 | F28: ='Other Exp'!I26 -> 500 | G28: ='Other Exp'!J26 -> 225 | H28: ='Other Exp'!K26 -> 0 | I28: ='Other Exp'!L26 -> 0 | J28: ='Other Exp'!M26 -> 0 | ... N28: ='Other Exp'!Q26 -> 500 | O28: =SUM(C28:N28) -> 2825
A29: OtherExp | B29: Delivery, Maintenance and Repairs | C29: ='Other Exp'!F31 -> 300 | D29: ='Other Exp'!G31 -> 300 | E29: ='Other Exp'!H31 -> 300 | F29: ='Other Exp'!I31 -> 300 | G29: ='Other Exp'!J31 -> 300 | H29: ='Other Exp'!K31 -> 300 | I29: ='Other Exp'!L31 -> 300 | J29: ='Other Exp'!M31 -> 300 | ... N29: ='Other Exp'!Q31 -> 500 | O29: =SUM(C29:N29) -> 4200
A30: OtherExp | B30: Insurance | C30: ='Other Exp'!$F$33 -> 110 | D30: ='Other Exp'!$F$33 -> 110 | E30: ='Other Exp'!$F$33 -> 110 | F30: ='Other Exp'!$F$33 -> 110 | G30: ='Other Exp'!$F$33 -> 110 | H30: ='Other Exp'!$F$33 -> 110 | I30: ='Other Exp'!$F$33 -> 110 | J30: ='Other Exp'!$F$33 -> 110 | ... N30: ='Other Exp'!$F$33 -> 110 | O30: =SUM(C30:N30) -> 1320
A31: OtherExp | B31: Other Expenses | C31: ='Other Exp'!$F$35 -> 2900 | D31: ='Other Exp'!$F$35 -> 2900 | E31: ='Other Exp'!$F$35 -> 2900 | F31: ='Other Exp'!$F$35 -> 2900 | G31: ='Other Exp'!$F$35 -> 2900 | H31: ='Other Exp'!$F$35 -> 2900 | I31: ='Other Exp'!$F$35 -> 2900 | J31: ='Other Exp'!$F$35 -> 2900 | ... N31: ='Other Exp'!$F$35 -> 2900 | O31: =SUM(C31:N31) -> 34800
A32: OtherExp | B32: Bank Charges | C32: ='Other Exp'!$F$37 -> 40 | D32: ='Other Exp'!$F$37 -> 40 | E32: ='Other Exp'!$F$37 -> 40 | F32: ='Other Exp'!$F$37 -> 40 | G32: ='Other Exp'!$F$37 -> 40 | H32: ='Other Exp'!$F$37 -> 40 | I32: ='Other Exp'!$F$37 -> 40 | J32: ='Other Exp'!$F$37 -> 40 | ... N32: ='Other Exp'!$F$37 -> 40 | O32: =SUM(C32:N32) -> 480
B33: Credit Card Fees | C33: =(C8+C11+C13)*Financing!$B$3 -> 11.4075 | D33: =(D8+D11+D13)*Financing!$B$3 -> 528.97 | E33: =(E8+E11+E13)*Financing!$B$3 -> 345.39375 | F33: =(F8+F11+F13)*Financing!$B$3 -> 373.38438 | G33: =(G8+G11+G13)*Financing!$B$3 -> 104.78 | H33: =(H8+H11+H13)*Financing!$B$3 -> 98.548125 | I33: =(I8+I11+I13)*Financing!$B$3 -> 343.80937 | J33: =(J8+J11+J13)*Financing!$B$3 -> 548.61625 | ... N33: =(N8+N11+N13)*Financing!$B$3 -> 1256.6206 | O33: =SUM(C33:N33) -> 7467.6875
A34: Financing | B34: Interest Repayment Loan | C34: =Financing!B25 -> 0 | D34: =Financing!C25 -> 102.08333 | E34: =Financing!D25 -> 96.551341 | F34: =Financing!E25 -> 91.003214 | G34: =Financing!F25 -> 85.438905 | H34: =Financing!G25 -> 79.858367 | I34: =Financing!H25 -> 74.261552 | J34: =Financing!I25 -> 68.648413 | ... N34: =Financing!M25 -> 46.031663 | O34: =SUM(C34:N34) -> 815.97924
B35: Interest Repayment LofC | C35: 0 | D35: =C51*Financing!$B$7 -> 0 | E35: =D51*Financing!$B$7 -> 0 | F35: =E51*Financing!$B$7 -> 0 | G35: =F51*Financing!$B$7 -> 0 | H35: =G51*Financing!$B$7 -> 0 | I35: =H51*Financing!$B$7 -> 28.966018 | J35: =I51*Financing!$B$7 -> 81.663222 | K35: =J51*Financing!$B$7 -> 127.20636 | ... N35: =M51*Financing!$B$7 -> 18.949411 | O35: =SUM(C35:N35) -> 603.91771
B36: Operating Outflow Subtotal | C36: =SUM(C22:C35) -> 18105.262 | D36: =SUM(D22:D35) -> 6814.9075 | E36: =SUM(E22:E35) -> 11783.199 | F36: =SUM(F22:F35) -> 12192.602 | G36: =SUM(G22:G35) -> 11831.473 | H36: =SUM(H22:H35) -> 9844.6607 | I36: =SUM(I22:I35) -> 10659.041 | J36: =SUM(J22:J35) -> 11456.682 | ... N36: =SUM(N22:N35) -> 14744.056 | O36: =SUM(C36:N36) -> 156524.54
A37: Assets | B37: Asset (Equipment) Purchases | C37: =Startup!C23 -> 43200 | O37: =SUM(C37:N37) -> 43200
B38: Principal Repayment LofC | C38: 0 | D38: =C51 -> 0 | E38: =D51 -> 0 | F38: =E51 -> 0 | G38: =F51 -> 0 | H38: =G51 -> 0 | I38: =H51 -> 4794.3754 | J38: =I51 -> 13516.671 | K38: =J51 -> 21054.846 | ... N38: =M51 -> 3136.4543 | O38: =SUM(C38:N38) -> 99958.793
A39: Financing | B39: Principal Repayment Loan | C39: =Financing!B26 -> 0 | D39: =Financing!C26 -> 1896.683 | E39: =Financing!D26 -> 1902.215 | F39: =Financing!E26 -> 1907.7631 | G39: =Financing!F26 -> 1913.3274 | H39: =Financing!G26 -> 1918.908 | I39: =Financing!H26 -> 1924.5048 | J39: =Financing!I26 -> 1930.1179 | ... N39: =Financing!M26 -> 1952.7347 | O39: =SUM(C39:N39) -> 21170.45
A40: Sales+Inv | B40: Inventory (Merchandise) Purchases | C40: ='Sales+Inv+Cost'!D53 -> 11226.25 | D40: ='Sales+Inv+Cost'!E53 -> 5703.75 | E40: ='Sales+Inv+Cost'!F53 -> 6093.75 | F40: ='Sales+Inv+Cost'!G53 -> 2096.25 | G40: ='Sales+Inv+Cost'!H53 -> 2340 | H40: ='Sales+Inv+Cost'!I53 -> 5923.125 | I40: ='Sales+Inv+Cost'!J53 -> 8433.75 | J40: ='Sales+Inv+Cost'!K53 -> 13528.125 | ... N40: ='Sales+Inv+Cost'!O53 -> 4182.75 | O40: =SUM(C40:N40) -> 130557.75
A41: HR | B41: Owner's Drawings | C41: 0 | D41: 0 | E41: 0 | F41: 0 | G41: ='HR Exp'!$E$4 -> 3500 | H41: ='HR Exp'!$E$4 -> 3500 | I41: ='HR Exp'!$E$4 -> 3500 | J41: ='HR Exp'!$E$4 -> 3500 | K41: ='HR Exp'!$E$4 -> 3500 | L41: ='HR Exp'!$E$4 -> 3500 | M41: ='HR Exp'!$E$4 -> 3500 | N41: ='HR Exp'!$E$4 -> 3500 | O41: =SUM(C41:N41) -> 28000
B42: Non-operating Outflow Subtotal | C42: =SUM(C37:C41) -> 54426.25 | D42: =SUM(D37:D41) -> 7600.433 | E42: =SUM(E37:E41) -> 7995.965 | F42: =SUM(F37:F41) -> 4004.0131 | G42: =SUM(G37:G41) -> 7753.3274 | H42: =SUM(H37:H41) -> 11342.033 | I42: =SUM(I37:I41) -> 18652.63 | J42: =SUM(J37:J41) -> 32474.914 | ... N42: =SUM(N37:N41) -> 12771.939 | O42: =SUM(C42:N42) -> 322886.99
...

Sheet IS
B1: The Chocolate Shop
B2: Proforma Income Statement
B3: January 2025 To December 2025
A5: Notes | C5: The Chocolate Shop Jan-25 to Dec-25 | E5: The Chocolate Shop % of sales | F5: Industry Benchmark % of sales | G5: Industry Canada Line Titles
A6: Sales+Inv | B6: Sales
B7: Factory | C7: =SUM('Sales+Inv+Cost'!B18:M18) -> 58500 | E7: =C7/$C$10 -> 0.18
B8: Tradeshow | C8: =SUM('Sales+Inv+Cost'!B25:M25) -> 156000 | E8: =C8/$C$10 -> 0.48
B9: Preorder | C9: =SUM('Sales+Inv+Cost'!B32:M32) -> 110500 | E9: =C9/$C$10 -> 0.34
B10: Total Sales | C10: =SUM(C7:C9) -> 325000 | E10: =C10/$C$10 -> 1 | F10: ='NAICS%'!E11% -> 1 | G10: Total Revenue
B12: Cost of Goods Sold
A13: HRExp | B13: Labour | C13: ='HR Exp'!Q24 -> 66095.71 | E13: =C13/$C$10 -> 0.20337142 | F13: ='NAICS%'!E15% -> 0.079000001 | G13: Wages and Benefits
A14: Sales+Inv | B14: Material | C14: =C10*'Sales+Inv+Cost'!B45 -> 121875 | E14: =C14/$C$10 -> 0.375 | F14: ='NAICS%'!E16% -> 0.34299999 | G14: Purchases, Martial, and Sub-contracts
B16: Total CoGS | C16: =SUM(C13:C14) -> 187970.71 | E16: =C16/$C$10 -> 0.57837142 | F16: ='NAICS%'!E14% -> 0.415 | G16: Cost of sales (direct expenses)
B18: Gross Profit | C18: =C10-C16 -> 137029.29 | E18: =C18/$C$10 -> 0.42162858
B20: Operating expenses
A21: Assets | B21: Depreciation | C21: =Assets!E8 -> 8691.1111 | E21: =C21/$C$10 -> 0.02674188 | F21: ='NAICS%'!E21% -> 0.045999999 | G21: Amortization and depletion
A22: CFF | B22: Start-up Expenses | C22: =CFF!O22 -> 11910
A23: CFF | B23: Repairs and Maintenance | C23: =CFF!O24 -> 3900 | E23: =C23/$C$10 -> 0.012 | F23: ='NAICS%'!E22% -> 0.016 | G23: Repairs and maintenance
A24: CFF | B24: Utilities and Telephone | C24: =CFF!O25 -> 4200 | E24: =C24/$C$10 -> 0.012923077 | F24: ='NAICS%'!E23% -> 0.019 | G24: Utilities and telephone/telecommunication
A25: CFF | B25: Rent | C25: =CFF!O26 -> 10306.25 | E25: =C25/$C$10 -> 0.031711538 | F25: ='NAICS%'!E24% -> 0.075999999 | G25: Rent
B26: Interest and Bank Charges | C26: =SUM(D27:D30) -> 9367.5844 | E26: =C26/$C$10 -> 0.028823337 | F26: ='NAICS%'!E25% -> 0.025 | G26: Interest and bank charges
A27: CFF | B27: Bank Charges | D27: =CFF!O32 -> 480
A28: CFF | B28: Credit Card Fees | D28: =CFF!O33 -> 7467.6875
A29: CFF | B29: Interest Repayment Loan | D29: =CFF!O34 -> 815.97924
A30: CFF | B30: Interest Repayment LoC | D30: =CFF!O35 -> 603.91771
A31: CFF | B31: Professional Fees and Memberships | C31: =CFF!O27 -> 7600 | E31: =C31/$C$10 -> 0.023384615 | F31: ='NAICS%'!E26% -> 0.025999999 | G31: Professional and business fees
A32: CFF | B32: Advertising and Promotions | C32: =CFF!O28 -> 2825 | E32: =C32/$C$10 -> 0.0086923077 | F32: ='NAICS%'!E27% -> 0.022 | G32: Advertising and promotion
A33: CFF | B33: Delivery, Shipping and Warehouse Expenses | C33: =CFF!O29 -> 4200 | E33: =C33/$C$10 -> 0.012923077 | F33: ='NAICS%'!E28% -> 0.0080000001 | G33: Delivery, shipping and warehouse expenses
A34: CFF | B34: Insurance | C34: =CFF!O30 -> 1320 | E34: =C34/$C$10 -> 0.0040615385 | F34: ='NAICS%'!E29% -> 0.011 | G34: Insurance
A35: CFF | B35: Other Expenses | C35: =CFF!O31 -> 34800 | E35: =C35/$C$10 -> 0.10707692 | F35: ='NAICS%'!E30% -> 0.093000002 | G35: Other Expenses
B36: Total Operating Exp | C36: =SUM(C20:C35) -> 99119.946 | E36: =SUM(E21:E35) -> 0.26833829 | F36: ='NAICS%'!E31% -> 0.995 | G36: Total expenses
B38: Total Operating Profit Before Taxes | C38: =C18-C36 -> 37909.344 | E38: =C38/$C$10 -> 0.11664414 | F38: ='NAICS%'!E32% -> 0.005 | G38: Net profit/loss
B41: Notes
B42: Start-up Expenses are not included in % calculation since it is a one time charge
B43: NAICS Lower Middle Quartile used for Comparison since the revenue falls into that range

Sheet BS
B1: The Chocolate Shop
B2: Proforma Balance sheet as of Dec 31, 2025
A4: Notes | C4: as of December 31, 2025
B5: Assets
B6: Current Assets
A7: CFF | B7: Cash on hand | C7: =CFF!N52 -> 30878.505
A8: Sales+Inv | B8: Inventories | C8: ='Sales+Inv+Cost'!P50 -> 8682.75
A9: Sales+Inv | B9: A/R | C9: ='Sales+Inv+Cost'!N38 -> 9668.75
B10: Total Current Assets | C10: =SUM(C7:C9) -> 49230.005
A12: Assets | B12: Long Term Assets
B13: LT Assets Original Value | C13: =Assets!B8 -> 55700
B14: Less: Accumulated Depreciation | C14: =Assets!E8 -> 8691.1111
B15: Total Net LT Assets | C15: =C13-C14 -> 47008.889
B17: Total Assets | C17: =C10+C15 -> 96238.894
B19: Liabilities and Equity
B20: Current Liabilities
A21: CFF | B21: Line of Credit | C21: =CFF!N51 -> 0
A22: Financing | B22: Loan | C22: =Financing!M27 -> 13829.55
B23: Long term Liabilities | C23: =SUM(C21:C22) -> 13829.55
B25: Total Liabilities | C25: =SUM(C21:C22) -> 13829.55
B28: Equity
B29: Opening owner's Equity | C29: 0
A30: IS | B30: Add profit (Less Loss) | C30: =IS!C38 -> 37909.344
A31: Startup | B31: Add Owner Inflow | C31: =CFF!O17 -> 60000
A32: Assets | B32: Add Capital Increase | C32: =Assets!B7 -> 12500
A33: HRExp | B33: Less Owner's Drawings | C33: =CFF!O41 -> 28000
B34: Owner's Equity | C34: =C29+C30+C31+C32-C33 -> 82409.344
B36: Total Liabilities + Equity | C36: =C25+C34 -> 96238.894 | E36: Assets - Liability | F36: =C17-C36 -> 0

Sheet Startup
A1: The Chocolate Shop
A2: Startup Expenses
A3: Description | B3: Expense | C3: Asset (Capital) | D3: Inventory | E3: Total
A4: Business Registration | B4: 75 | E4: =SUM(B4:D4) -> 75
A5: Chamber Membership | B5: 250 | E5: =SUM(B5:D5) -> 250
A6: Inventory for Jan Sales | D6: ='Sales+Inv+Cost'!B51 -> 438.75 | E6: =SUM(B6:D6) -> 438.75
A7: Inventory Safety Stock | D7: ='Sales+Inv+Cost'!B52 -> 2500 | E7: =SUM(B7:D7) -> 2500
A8: Leasehold Improvements | C8: =Assets!B6 -> 8500 | E8: =SUM(B8:D8) -> 8500
A9: Computer Equipment and POS | C9: =Assets!B4 -> 6450 | E9: =SUM(B9:D9) -> 6450
A10: Racking, Manufacturing Equipment | C10: =Assets!B5 -> 28250 | E10: =SUM(B10:D10) -> 28250
A11: Lawyer | B11: 600 | E11: =SUM(B11:D11) -> 600
A12: Accountant | B12: 450 | E12: =SUM(B12:D12) -> 450
A13: Computer Software | B13: 550 | E13: =SUM(B13:D13) -> 550
A14: Internet Domain | B14: 20 | E14: =SUM(B14:D14) -> 20
A15: Internet Installation | B15: 235 | E15: =SUM(B15:D15) -> 235
A16: Utilities Installation | B16: 450 | E16: =SUM(B16:D16) -> 450
A17: Utilities (startup period) | B17: 365 | E17: =SUM(B17:D17) -> 365
A18: Initial advertising and logo design | B18: 1250 | E18: =SUM(B18:D18) -> 1250
A19: Trade Booth Equipment | B19: 740 | E19: =SUM(B19:D19) -> 740
A20: Outdoor Signage and permit | B20: 1750 | E20: =SUM(B20:D20) -> 1750
A21: FICA Membership and Training | B21: 3225 | E21: =SUM(B21:D21) -> 3225
A22: Miscellaneous Startup | B22: 1950 | E22: =SUM(B22:D22) -> 1950
A23: Total Start-up Expenses | B23: =SUM(B4:B22) -> 11910 | C23: =SUM(C4:C22) -> 43200 | D23: =SUM(D4:D22) -> 2938.75 | E23: =SUM(E4:E22) -> 58048.75
A25: Notes:
A26: Calculated cells will showcase referenced cell from respective worksheet.
A27: Assets and Inventory expenses are referenced from "Asset" and "Inventory" worksheet respectively.
A29: The Chocolate shop
A30: Startup Cash Requirements
A32: Inflows
A33: Owner Investment | B33: 60000
A35: Startup Requirement = Startup Expenses + 3 to 6 months operating expenses - Investment

Sheet Sales+Inv+Cost
A1: Sales Projections
A3: Estimated Total sales for year 1( Jan 2025- Dec 2025) | C3: 325000
B5: Factory | C5: Tradeshows/Markets | D5: Preorders
A6: % of Sales Mix | B6: 0.18 | C6: 0.48 | D6: 0.34
A7: Year 1 Estimated Sales | B7: =B6*$C$3 -> 58500 | C7: =C6*$C$3 -> 156000 | D7: =D6*$C$3 -> 110500
A8: Year 2 Estimated Sales Increase | B8: 0.32 | C8: 0.32 | D8: 0.32
A9: Year 2 Estimated Sales | B9: =B7*(1+B8) -> 77220 | C9: =C7*(1+C8) -> 205920 | D9: =D7*(1+D8) -> 145860
A11: Cash Sales- % of Total Retail sales | B11: 0.7 | C11: 0.1 | D11: 0
A12: Credit Card Sales- % of Total Retail Sales | B12: =1-B11 -> 0.3 | C12: =1-C11 -> 0.9 | D12: 0.65
A13: Net - 30 | D13: =1-D12 -> 0.35
B15: 1 | C15: 2 | D15: 3 | E15: 4 | F15: 5 | G15: 6 | H15: 7 | I15: 8 | J15: 9 | K15: 10 | L15: 11 | M15: 12 | N15: 13 | O15: Total
A16: Year 1 sales | B16: 45658 | C16: 45689 | D16: 45717 | E16: 45748 | F16: 45778 | G16: 45809 | H16: 45839 | I16: 45870 | J16: 45901 | K16: 45931 | L16: 45962 | M16: 45992 | N16: 46023
A17: Factory Seasonality Pattern | B17: 0.02 | C17: 0.04 | D17: 0.04 | E17: 0.05 | F17: 0.02 | G17: 0.05 | H17: 0.08 | I17: 0.08 | J17: 0.1 | K17: 0.12 | L17: 0.18 | M17: 0.22 | N17: 0.05 | O17: =SUM(B17:M17) -> 1
A18: Total Factory Sales | B18: =$B$7*B17 -> 1170 | C18: =$B$7*C17 -> 2340 | D18: =$B$7*D17 -> 2340 | E18: =$B$7*E17 -> 2925 | F18: =$B$7*F17 -> 1170 | G18: =$B$7*G17 -> 2925 | H18: =$B$7*H17 -> 4680 | I18: =$B$7*I17 -> 4680 | ... M18: =$B$7*M17 -> 12870 | N18: =$B$9*N17 -> 3861 | O18: =SUM(B18:M18) -> 58500
A19: Factory Sales-Cash | B19: =B18*$B$11 -> 819 | C19: =C18*$B$11 -> 1638 | D19: =D18*$B$11 -> 1638 | E19: =E18*$B$11 -> 2047.5 | F19: =F18*$B$11 -> 819 | G19: =G18*$B$11 -> 2047.5 | H19: =H18*$B$11 -> 3276 | I19: =I18*$B$11 -> 3276 | ... N19: =N18*$B$11 -> 2702.7 | O19: =SUM(B19:M19) -> 40950
A20: Factory Sales-Credit | B20: =B18*$B$12 -> 351 | C20: =C18*$B$12 -> 702 | D20: =D18*$B$12 -> 702 | E20: =E18*$B$12 -> 877.5 | F20: =F18*$B$12 -> 351 | G20: =G18*$B$12 -> 877.5 | H20: =H18*$B$12 -> 1404 | I20: =I18*$B$12 -> 1404 | ... N20: =N18*$B$12 -> 1158.3 | O20: =SUM(B20:M20) -> 17550 | R20: =SUM(B19:M20) -> 58500
B22: 1 | C22: 2 | D22: 3 | E22: 4 | F22: 5 | G22: 6 | H22: 7 | I22: 8 | J22: 9 | K22: 10 | L22: 11 | M22: 12 | N22: 13 | O22: Total
A23: Year 1 sales | B23: 45658 | C23: 45689 | D23: 45717 | E23: 45748 | F23: 45778 | G23: 45809 | H23: 45839 | I23: 45870 | J23: 45901 | K23: 45931 | L23: 45962 | M23: 45992 | N23: 46023
A24: Tradeshows Seasonality Pattern | B24: 0 | C24: 0.07 | D24: 0.04 | E24: 0.05 | F24: 0 | G24: 0 | H24: 0.05 | I24: 0.1 | J24: 0.13 | K24: 0.19 | L24: 0.25 | M24: 0.12 | N24: 0 | O24: =SUM(B24:M24) -> 1
A25: Total Tradeshows Sales | B25: =$C$7*B24 -> 0 | C25: =$C$7*C24 -> 10920 | D25: =$C$7*D24 -> 6240 | E25: =$C$7*E24 -> 7800 | F25: =$C$7*F24 -> 0 | G25: =$C$7*G24 -> 0 | H25: =$C$7*H24 -> 7800 | I25: =$C$7*I24 -> 15600 | ... M25: =$C$7*M24 -> 18720 | N25: =$C$9*N24 -> 0 | O25: =SUM(B25:M25) -> 156000
A26: Tradeshows Sales-Cash | B26: =B25*$C$11 -> 0 | C26: =C25*$C$11 -> 1092 | D26: =D25*$C$11 -> 624 | E26: =E25*$C$11 -> 780 | F26: =F25*$C$11 -> 0 | G26: =G25*$C$11 -> 0 | H26: =H25*$C$11 -> 780 | I26: =I25*$C$11 -> 1560 | ... N26: =N25*$C$11 -> 0 | O26: =SUM(B26:M26) -> 15600
A27: Tradeshows Sales-Credit | B27: =B25*$C$12 -> 0 | C27: =C25*$C$12 -> 9828 | D27: =D25*$C$12 -> 5616 | E27: =E25*$C$12 -> 7020 | F27: =F25*$C$12 -> 0 | G27: =G25*$C$12 -> 0 | H27: =H25*$C$12 -> 7020 | I27: =I25*$C$12 -> 14040 | ... N27: =N25*$C$12 -> 0 | O27: =SUM(B27:M27) -> 140400 | R27: =SUM(B26:M27) -> 156000
B29: 1 | C29: 2 | D29: 3 | E29: 4 | F29: 5 | G29: 6 | H29: 7 | I29: 8 | J29: 9 | K29: 10 | L29: 11 | M29: 12 | N29: 13 | O29: Total
A30: Year 1 sales | B30: 45658 | C30: 45689 | D30: 45717 | E30: 45748 | F30: 45778 | G30: 45809 | H30: 45839 | I30: 45870 | J30: 45901 | K30: 45931 | L30: 45962 | M30: 45992 | N30: 46023
A31: Preorders Seasonality Pattern | B31: 0 | C31: 0.08 | D31: 0.06 | E31: 0.05 | F31: 0.04 | G31: 0.03 | H31: 0.03 | I31: 0.02 | J31: 0.09 | K31: 0.16 | L31: 0.19 | M31: 0.25 | N31: 0.05 | O31: =SUM(B31:M31) -> 1
A32: Total Preorders Sales | B32: =B31*$D$7 -> 0 | C32: =C31*$D$7 -> 8840 | D32: =D31*$D$7 -> 6630 | E32: =E31*$D$7 -> 5525 | F32: =F31*$D$7 -> 4420 | G32: =G31*$D$7 -> 3315 | H32: =H31*$D$7 -> 3315 | I32: =I31*$D$7 -> 2210 | ... M32: =M31*$D$7 -> 27625 | N32: =N31*$D$9 -> 7293 | O32: =SUM(B32:M32) -> 110500
A33: Preorders Sales-Credit | B33: =B32*$D$12 -> 0 | C33: =C32*$D$12 -> 5746 | D33: =D32*$D$12 -> 4309.5 | E33: =E32*$D$12 -> 3591.25 | F33: =F32*$D$12 -> 2873 | G33: =G32*$D$12 -> 2154.75 | H33: =H32*$D$12 -> 2154.75 | I33: =I32*$D$12 -> 1436.5 | ... N33: =N32*$D$12 -> 4740.45 | O33: =SUM(B33:M33) -> 71825
A34: Preorders Sales-Net 30 | B34: =B32*$D$13 -> 0 | C34: =C32*$D$13 -> 3094 | D34: =D32*$D$13 -> 2320.5 | E34: =E32*$D$13 -> 1933.75 | F34: =F32*$D$13 -> 1547 | G34: =G32*$D$13 -> 1160.25 | H34: =H32*$D$13 -> 1160.25 | I34: =I32*$D$13 -> 773.5 | ... N34: =N32*$D$13 -> 2552.55 | O34: =SUM(B34:M34) -> 38675 | R34: =SUM(B33:M34) -> 110500
A36: Total Sales | B36: =SUM(B18+B25+B32) -> 1170 | C36: =SUM(C18+C25+C32) -> 22100 | D36: =SUM(D18+D25+D32) -> 15210 | E36: =SUM(E18+E25+E32) -> 16250 | F36: =SUM(F18+F25+F32) -> 5590 | G36: =SUM(G18+G25+G32) -> 6240 | H36: =SUM(H18+H25+H32) -> 15795 | I36: =SUM(I18+I25+I32) -> 22490 | ... N36: =SUM(N18+N25+N32) -> 11154 | O36: =SUM(B36:M36) -> 325000 | R36: =SUM(R20,R27,R34) -> 325000
A38: Net 30 Preorder Sales Collected (A/R) | B38: 0 | C38: =B34 -> 0 | D38: =C34 -> 3094 | E38: =D34 -> 2320.5 | F38: =E34 -> 1933.75 | G38: =F34 -> 1547 | H38: =G34 -> 1160.25 | I38: =H34 -> 1160.25 | J38: =I34 -> 773.5 | ... N38: =M34 -> 9668.75 | O38: =SUM(B38:M38) -> 29006.25
A43: Inventory and Cost of Goods Sold
A45: Cost of good sold | B45: 0.375 | C45: One month in advance of sales
D47: 1 | E47: 2 | F47: 3 | G47: 4 | H47: 5 | I47: 6 | J47: 7 | K47: 8 | L47: 9 | M47: 10 | N47: 11 | O47: 12 | P47: 13
B48: Start-up | C48: 45682 | D48: Startup + Jan-25 | E48: 45713 | F48: 45741 | G48: 45772 | H48: 45802 | I48: 45833 | J48: 45863 | K48: 45894 | L48: 45925 | M48: 45955 | N48: 45986 | O48: 46016 | P48: 46047
A49: Memo Total Sales | B49: 0 | C49: =B36 -> 1170 | D49: =B36 -> 1170 | E49: =C36 -> 22100 | F49: =D36 -> 15210 | G49: =E36 -> 16250 | H49: =F36 -> 5590 | I49: =G36 -> 6240 | J49: =H36 -> 15795 | K49: =I36 -> 22490 | ... P49: =N36 -> 11154
A50: Inventory on hand | B50: 0 | C50: =B55 -> 2938.75 | D50: =B50 -> 0 | E50: =D55 -> 10787.5 | F50: =E55 -> 8203.75 | G50: =F55 -> 8593.75 | H50: =G55 -> 4596.25 | I50: =H55 -> 4840 | J50: =I55 -> 8423.125 | K50: =J55 -> 10933.75 | L50: =K55 -> 16028.125 | ... P50: =O55 -> 8682.75
A51: Advance Stock | B51: =C49*$B$45 -> 438.75 | C51: =$B$45*E49 -> 8287.5 | D51: =B51+C51 -> 8726.25 | E51: =F49*$B$45 -> 5703.75 | F51: =G49*$B$45 -> 6093.75 | G51: =H49*$B$45 -> 2096.25 | H51: =I49*$B$45 -> 2340 | I51: =J49*$B$45 -> 5923.125 | J51: =K49*$B$45 -> 8433.75 | K51: =L49*$B$45 -> 13528.125 | L51: =M49*$B$45 -> 20377.5 | ... O51: =P49*$B$45 -> 4182.75
A52: Plus: Safety stock purchased | B52: 2500 | C52: 0 | D52: =B52+C52 -> 2500 | E52: 0 | F52: 0 | G52: 0 | H52: 0 | I52: 0 | J52: 0 | K52: 0 | L52: 2000 | M52: 0 | N52: 0 | O52: 0
A53: Subtotal: Purchases | B53: =SUM(B51:B52) -> 2938.75 | C53: =SUM(C51:C52) -> 8287.5 | D53: =SUM(D51:D52) -> 11226.25 | E53: =SUM(E51:E52) -> 5703.75 | F53: =SUM(F51:F52) -> 6093.75 | G53: =SUM(G51:G52) -> 2096.25 | H53: =SUM(H51:H52) -> 2340 | I53: =SUM(I51:I52) -> 5923.125 | ... O53: =SUM(O51:O52) -> 4182.75
A54: Less: Material cost of goods sold | B54: =$B$45*B49 -> 0 | C54: =$B$45*C49 -> 438.75 | D54: =$B$45*D49 -> 438.75 | E54: =$B$45*E49 -> 8287.5 | F54: =$B$45*F49 -> 5703.75 | G54: =$B$45*G49 -> 6093.75 | H54: =$B$45*H49 -> 2096.25 | I54: =$B$45*I49 -> 2340 | ... O54: =$B$45*O49 -> 22205.625
...

Sheet Assets
A1: Assets and Depreciation
A3: Description | B3: Cost | C3: useful life (yrs) | D3: Value end | E3: Yearly Depreciation
A4: Leasehold Improvements | B4: 6450 | C4: 2.5 | D4: 0 | E4: =SLN(B4,D4,C4) -> 2580
A5: Racking, Manufacturing Equipment | B5: 28250 | C5: 18 | D5: 0 | E5: =SLN(B5,D5,C5) -> 1569.4444
A6: Office Computer and POS | B6: 8500 | C6: 6 | D6: 0 | E6: =SLN(B6,D6,C6) -> 1416.6667
A7: Van | B7: 12500 | C7: 4 | D7: 0 | E7: =SLN(B7,D7,C7) -> 3125
A8: Total | B8: =SUM(B4:B7) -> 55700 | D8: =SUM(D4:D7) -> 0 | E8: =SUM(E4:E7) -> 8691.1111
A11: Yearly Depreciation Summary
B12: 2025
A13: Original Cost | B13: =B8 -> 55700
A14: Accumulated Depreciation | B14: =SUM(E4:E7) -> 8691.1111

Sheet HR Exp
A1: Human Resource Expenses
A3: Owner's Drawings
A4: Owner Draw Per Month | E4: 3500 | F4: Starts in May 2025
A5: Owner Gov't Payroll Tax % | E5: 0
A6: Owner Benefits Per Month | E6: 0
A7: Owner % Production | E7: 0.5
A9: Wages and Salary Factors
A10: Full Time Hrs Per Month | E10: 160
A11: Full Time Wages Per Hour | E11: 24.5
A12: Full Time Payroll Tax and Benefits % | E12: 0.22
A14: Part Time Wage Per Hour | E14: 18.5
A15: Part Time Payroll Tax and Benefits % | E15: 0.18
E17: 1 | F17: 2 | G17: 3 | H17: 4 | I17: 5 | J17: 6 | K17: 7 | L17: 8 | M17: 9 | N17: 10 | O17: 11 | P17: 12
A18: Calculation Of wages and Salaries | E18: 45658 | F18: 45689 | G18: 45717 | H18: 45748 | I18: 45778 | J18: 45809 | K18: 45839 | L18: 45870 | M18: 45901 | N18: 45931 | O18: 45962 | P18: 45992 | Q18: Total
A19: Part time Employee - Hours Per Month | E19: 0 | F19: 0 | G19: 0 | H19: 12 | I19: 0 | J19: 0 | K19: 25 | L19: 50 | M19: 160 | N19: 200 | O19: 250 | P19: 140 | Q19: =SUM(E19:P19) -> 837
A20: Part Time Wages | E20: =E19*$E$14 -> 0 | F20: =F19*$E$14 -> 0 | G20: =G19*$E$14 -> 0 | H20: =H19*$E$14 -> 222 | I20: =I19*$E$14 -> 0 | J20: =J19*$E$14 -> 0 | K20: =K19*$E$14 -> 462.5 | L20: =L19*$E$14 -> 925 | ... P20: =P19*$E$14 -> 2590 | Q20: =SUM(E20:P20) -> 15484.5
A21: Part Time Benefits and Payroll Taxes | E21: =E20*$E$15 -> 0 | F21: =F20*$E$15 -> 0 | G21: =G20*$E$15 -> 0 | H21: =H20*$E$15 -> 39.96 | I21: =I20*$E$15 -> 0 | J21: =J20*$E$15 -> 0 | K21: =K20*$E$15 -> 83.25 | L21: =L20*$E$15 -> 166.5 | ... P21: =P20*$E$15 -> 466.2 | Q21: =SUM(E21:P21) -> 2787.21
A22: Full Time Wages | E22: 0 | F22: 0 | G22: =$E$11*$E$10 -> 3920 | H22: =$E$11*$E$10 -> 3920 | I22: =$E$11*$E$10 -> 3920 | J22: =$E$11*$E$10 -> 3920 | K22: =$E$11*$E$10 -> 3920 | L22: =$E$11*$E$10 -> 3920 | M22: =$E$11*$E$10 -> 3920 | N22: =$E$11*$E$10 -> 3920 | ... P22: =$E$11*$E$10 -> 3920 | Q22: =SUM(E22:P22) -> 39200
A23: Full Time Benefits and Payroll Taxes | E23: =E22*$E$12 -> 0 | F23: =F22*$E$12 -> 0 | G23: =G22*$E$12 -> 862.4 | H23: =H22*$E$12 -> 862.4 | I23: =I22*$E$12 -> 862.4 | J23: =J22*$E$12 -> 862.4 | K23: =K22*$E$12 -> 862.4 | L23: =L22*$E$12 -> 862.4 | ... P23: =P22*$E$12 -> 862.4 | Q23: =SUM(E23:P23) -> 8624 | S23: =SUM(E20:P23) -> 66095.71
A24: Total Wages and Benefits | E24: =SUM(E20:E23) -> 0 | F24: =SUM(F20:F23) -> 0 | G24: =SUM(G20:G23) -> 4782.4 | H24: =SUM(H20:H23) -> 5044.36 | I24: =SUM(I20:I23) -> 4782.4 | J24: =SUM(J20:J23) -> 4782.4 | K24: =SUM(K20:K23) -> 5328.15 | L24: =SUM(L20:L23) -> 5873.9 | ... P24: =SUM(P20:P23) -> 7838.6 | Q24: =SUM(E24:P24) -> 66095.71

Sheet Financing
A1: Financing
A3: Credit Card Fees | B3: 0.0325
A5: Line of Credit Factors
A6: Interest Rate | B6: 0.0725
A7: Interest Rate/month | B7: =B6/12 -> 0.0060416667
A8: Credit Limit | B8: 100000
A10: Contingency Amount | B10: 1500
A12: Loan Calculation Worksheet- Parent's Loan
A13: Interest Rate | B13: 0.035
A14: Interest Rate/mth | B14: =B13/12 -> 0.0029166667
A15: Period | B15: 18
A16: Amount of Loan (PV) | B16: 35000
A17: Final Loan Balance (FV) | B17: 0
A18: Monthly Payment | B18: =-PMT(B14,B15,B16,B17,) -> 1998.7663
A20: Loan Payment Table - Parent's Loan | B20: 1 | C20: 2 | D20: 3 | E20: 4 | F20: 5 | G20: 6 | H20: 7 | I20: 8 | J20: 9 | K20: 10 | L20: 11 | M20: 12 | N20: Total
A21: Year 1 | B21: 45658 | C21: 45689 | D21: 45717 | E21: 45748 | F21: 45778 | G21: 45809 | H21: 45839 | I21: 45870 | J21: 45901 | K21: 45931 | L21: 45962 | M21: 45992
A22: Payment Number | C22: 1 | D22: 2 | E22: 3 | F22: 4 | G22: 5 | H22: 6 | I22: 7 | J22: 8 | K22: 9 | L22: 10 | M22: 11
A23: Opening balance | B23: 0 | C23: =B16 -> 35000 | D23: =C27 -> 33103.317 | E23: =D27 -> 31201.102 | F23: =E27 -> 29293.339 | G23: =F27 -> 27380.011 | H23: =G27 -> 25461.104 | I23: =H27 -> 23536.599 | J23: =I27 -> 21606.481 | K23: =J27 -> 19670.733 | ... M23: =L27 -> 15782.284
A24: Payment | B24: 0 | C24: =$B$18 -> 1998.7663 | D24: =$B$18 -> 1998.7663 | E24: =$B$18 -> 1998.7663 | F24: =$B$18 -> 1998.7663 | G24: =$B$18 -> 1998.7663 | H24: =$B$18 -> 1998.7663 | I24: =$B$18 -> 1998.7663 | J24: =$B$18 -> 1998.7663 | ... M24: =$B$18 -> 1998.7663 | N24: =SUM(C24:M24) -> 21986.43
A25: Interest portion of payment | B25: 0 | C25: =-IPMT($B$14,C22,$B$15,$B$16,$B$17) -> 102.08333 | D25: =-IPMT($B$14,D22,$B$15,$B$16,$B$17) -> 96.551341 | E25: =-IPMT($B$14,E22,$B$15,$B$16,$B$17) -> 91.003214 | F25: =-IPMT($B$14,F22,$B$15,$B$16,$B$17) -> 85.438905 | G25: =-IPMT($B$14,G22,$B$15,$B$16,$B$17) -> 79.858367 | H25: =-IPMT($B$14,H22,$B$15,$B$16,$B$17) -> 74.261552 | I25: =-IPMT($B$14,I22,$B$15,$B$16,$B$17) -> 68.648413 | J25: =-IPMT($B$14,J22,$B$15,$B$16,$B$17) -> 63.018902 | ... M25: =-IPMT($B$14,M22,$B$15,$B$16,$B$17) -> 46.031663 | N25: =SUM(C25:M25) -> 815.97924
A26: Principal portion of payment | B26: 0 | C26: =-PPMT($B$14,C22,$B$15,$B$16,$B$17) -> 1896.683 | D26: =-PPMT($B$14,D22,$B$15,$B$16,$B$17) -> 1902.215 | E26: =-PPMT($B$14,E22,$B$15,$B$16,$B$17) -> 1907.7631 | F26: =-PPMT($B$14,F22,$B$15,$B$16,$B$17) -> 1913.3274 | G26: =-PPMT($B$14,G22,$B$15,$B$16,$B$17) -> 1918.908 | H26: =-PPMT($B$14,H22,$B$15,$B$16,$B$17) -> 1924.5048 | I26: =-PPMT($B$14,I22,$B$15,$B$16,$B$17) -> 1930.1179 | J26: =-PPMT($B$14,J22,$B$15,$B$16,$B$17) -> 1935.7474 | ... M26: =-PPMT($B$14,M22,$B$15,$B$16,$B$17) -> 1952.7347 | N26: =SUM(C26:M26) -> 21170.45
A27: Closing balance | B27: 0 | C27: =C23-C26 -> 33103.317 | D27: =D23-D26 -> 31201.102 | E27: =E23-E26 -> 29293.339 | F27: =F23-F26 -> 27380.011 | G27: =G23-G26 -> 25461.104 | H27: =H23-H26 -> 23536.599 | I27: =I23-I26 -> 21606.481 | J27: =J23-J26 -> 19670.733 | ... M27: =M23-M26 -> 13829.55
A29: Year 2 | B29: 46048 | C29: 46079 | D29: 46107 | E29: 46138 | F29: 46168 | G29: 46199 | H29: 46229 | I29: 46260 | J29: 46291 | K29: 46321 | L29: 46352 | M29: 46382 | N29: Total
A30: Payment Number | B30: 12 | C30: 13 | D30: 14 | E30: 15 | F30: 16 | G30: 17 | H30: 18 | I30: 19 | J30: 20 | K30: 21 | L30: 22 | M30: 23
A31: Opening balance | B31: =M27 -> 13829.55 | C31: =B35 -> 11871.12 | D31: =C35 -> 9906.9773 | E31: =D35 -> 7937.1063 | F31: =E35 -> 5961.4899 | G31: =F35 -> 3980.1112 | H31: =G35 -> 1992.9535 | I31: =H35 -> 4.3200998e-12 | J31: =I35 -> 0 | ... M31: =L35 -> 0
A32: Payment | B32: =$B$18 -> 1998.7663 | C32: =$B$18 -> 1998.7663 | D32: =$B$18 -> 1998.7663 | E32: =$B$18 -> 1998.7663 | F32: =$B$18 -> 1998.7663 | G32: =$B$18 -> 1998.7663 | H32: =$B$18 -> 1998.7663 | I32: =H36 -> 0 | J32: =I36 -> 0 | K32: =J36 -> 0 | L32: =K36 -> 0 | M32: =L36 -> 0 | N32: =SUM(B32:M32) -> 13991.364
A33: Interest portion of payment | B33: =-IPMT($B$14,B30,$B$15,$B$16,$B$17) -> 40.336186 | C33: =-IPMT($B$14,C30,$B$15,$B$16,$B$17) -> 34.624099 | D33: =-IPMT($B$14,D30,$B$15,$B$16,$B$17) -> 28.89535 | E33: =-IPMT($B$14,E30,$B$15,$B$16,$B$17) -> 23.149893 | F33: =-IPMT($B$14,F30,$B$15,$B$16,$B$17) -> 17.387679 | G33: =-IPMT($B$14,G30,$B$15,$B$16,$B$17) -> 11.608658 | H33: =-IPMT($B$14,H30,$B$15,$B$16,$B$17) -> 5.8127812 | I33: =H37 -> 0 | J33: =I37 -> 0 | K33: =J37 -> 0 | L33: =K37 -> 0 | M33: =L37 -> 0 | N33: =SUM(B33:M33) -> 161.81465
A34: Principal portion of payment | B34: =-PPMT($B$14,B30,$B$15,$B$16,$B$17) -> 1958.4301 | C34: =-PPMT($B$14,C30,$B$15,$B$16,$B$17) -> 1964.1422 | D34: =-PPMT($B$14,D30,$B$15,$B$16,$B$17) -> 1969.871 | E34: =-PPMT($B$14,E30,$B$15,$B$16,$B$17) -> 1975.6164 | F34: =-PPMT($B$14,F30,$B$15,$B$16,$B$17) -> 1981.3786 | G34: =-PPMT($B$14,G30,$B$15,$B$16,$B$17) -> 1987.1577 | H34: =-PPMT($B$14,H30,$B$15,$B$16,$B$17) -> 1992.9535 | I34: =H38 -> 0 | J34: =I38 -> 0 | K34: =J38 -> 0 | L34: =K38 -> 0 | M34: =L38 -> 0 | N34: =SUM(B34:M34) -> 13829.55
A35: Closing balance | B35: =B31-B34 -> 11871.12 | C35: =C31-C34 -> 9906.9773 | D35: =D31-D34 -> 7937.1063 | E35: =E31-E34 -> 5961.4899 | F35: =F31-F34 -> 3980.1112 | G35: =G31-G34 -> 1992.9535 | H35: =H31-H34 -> 4.3200998e-12 | I35: =H39 -> 0 | J35: =I39 -> 0 | K35: =J39 -> 0 | L35: =K39 -> 0 | M35: =L39 -> 0

Sheet Other Exp
A1: Other Expenses
A3: Repairs, Maintenance and cleaning | F3: 325 | G3: Monthly
A5: Utilities and Telephone
A6: Utilities | F6: 200 | G6: Monthly
A7: Telephone/Internet | F7: 150 | G7: Monthly
A8: Subtotal Utilities and Telephone | F8: =F6+F7 -> 350 | G8: Monthly
A10: Lease and Location Expense
A11: Sq. Footage | F11: 425
A12: Rental Cost Per ft per year | F12: 21.75
A13: CAM Cost per ft per year | F13: 2.5
A14: Annual Lease And Location Expenses | F14: =(F11*F12)+(F11*F13) -> 10306.25 | G14: Yearly
A15: Monthly Total Lease and Location Expense | F15: =F14/12 -> 858.85417 | G15: Monthly
A17: Professional Fees and Memberships | F17: 45682 | G17: 45713 | H17: 45741 | I17: 45772 | J17: 45802 | K17: 45833 | L17: 45863 | M17: 45894 | N17: 45925 | O17: 45955 | P17: 45986 | Q17: 46016 | R17: Total
A18: Greater K-W Chamber of commerce | F18: 0 | G18: 0 | H18: 0 | I18: 0 | J18: 450 | K18: 0 | L18: 0 | M18: 0 | N18: 0 | O18: 0 | P18: 0 | Q18: 0 | R18: =SUM(F18:Q18) -> 450
A19: Fine Chocolate Industry Association (FCIA) | F19: 0 | G19: 0 | H19: 0 | I19: 0 | J19: 0 | K19: 0 | L19: 0 | M19: 0 | N19: 0 | O19: 650 | P19: 0 | Q19: 0 | R19: =SUM(F19:Q19) -> 650
A20: Lawyer and Accountant | F20: 1300 | G20: 1300 | H20: 1300 | I20: 1300 | J20: 1300 | K20: 0 | L20: 0 | M20: 0 | N20: 0 | O20: 0 | P20: 0 | Q20: 0 | R20: =SUM(F20:Q20) -> 6500
A21: Subtotal Professional Fees and Memberships | F21: =SUM(F18:F20) -> 1300 | G21: =SUM(G18:G20) -> 1300 | H21: =SUM(H18:H20) -> 1300 | I21: =SUM(I18:I20) -> 1300 | J21: =SUM(J18:J20) -> 1750 | K21: =SUM(K18:K20) -> 0 | L21: =SUM(L18:L20) -> 0 | M21: =SUM(M18:M20) -> 0 | ... Q21: =SUM(Q18:Q20) -> 0 | R21: =SUM(F21:Q21) -> 7600
A23: Marketing
A24: Display Booth at Chamber Events | F24: 0 | G24: 0 | H24: 150 | I24: 150 | J24: 0 | K24: 0 | L24: 0 | M24: 0 | N24: 150 | O24: 0 | P24: 150 | Q24: 150 | R24: =SUM(H24:Q24) -> 750
A25: Tradeshows and Markets | F25: 0 | G25: 0 | H25: 225 | I25: 350 | J25: 225 | K25: 0 | L25: 0 | M25: 0 | N25: 350 | O25: 350 | P25: 225 | Q25: 350 | R25: =SUM(H25:Q25) -> 2075
A26: Subtotal Marketing | F26: =SUM(F24:F25) -> 0 | G26: =SUM(G24:G25) -> 0 | H26: =SUM(H24:H25) -> 375 | I26: =SUM(I24:I25) -> 500 | J26: =SUM(J24:J25) -> 225 | K26: =SUM(K24:K25) -> 0 | L26: =SUM(L24:L25) -> 0 | M26: =SUM(M24:M25) -> 0 | ... Q26: =SUM(Q24:Q25) -> 500 | R26: =SUM(H26:Q26) -> 2825
A28: Delivery, Maintenance and Repairs | F28: 300 | G28: Monthly
A29: Delivery Monthly | F29: =$F$28 -> 300 | G29: =$F$28 -> 300 | H29: =$F$28 -> 300 | I29: =$F$28 -> 300 | J29: =$F$28 -> 300 | K29: =$F$28 -> 300 | L29: =$F$28 -> 300 | M29: =$F$28 -> 300 | ... Q29: =$F$28 -> 300 | R29: =SUM(F29:Q29) -> 3600
A30: Extra Delivery Fees | F30: 0 | G30: 0 | H30: 0 | I30: 0 | J30: 0 | K30: 0 | L30: 0 | M30: 0 | N30: 0 | O30: 200 | P30: 200 | Q30: 200 | R30: =SUM(F30:Q30) -> 600
A31: Subtotal Delivery, Maintenance and Repairs | F31: =SUM(F29:F30) -> 300 | G31: =SUM(G29:G30) -> 300 | H31: =SUM(H29:H30) -> 300 | I31: =SUM(I29:I30) -> 300 | J31: =SUM(J29:J30) -> 300 | K31: =SUM(K29:K30) -> 300 | L31: =SUM(L29:L30) -> 300 | M31: =SUM(M29:M30) -> 300 | ... Q31: =SUM(Q29:Q30) -> 500 | R31: =SUM(F31:Q31) -> 4200
A33: Insurance - Content | F33: 110 | G33: Monthly
A35: Other Expenses | F35: 2900 | G35: Monthly
A37: Bank Charges | F37: 40 | G37: Monthly

Sheet NAICS%
A1: NAICS% (2023)
B3: Whole industry (reliability) | C3: Bottom quartile (25%) | D3: Lower middle (25%) | E3: Upper middle (25%) | F3: Top quartile (25%) | G3: Percentage of businesses reporting
A5: Number of businesses | B5: 182
A6: Revenue range:
A7: Low Value ($000) | B7: 30 | C7: 30 | D7: 74 | E7: 214 | F7: 722
A8: High Value ($000) | B8: 5000 | C8: 74 | D8: 214 | E8: 722 | F8: 5000
A10: Revenues and expenses | B10: (percentage of total revenue) - Averages
A11: Total revenue | B11: 100 | C11: 100 | D11: 100 | E11: 100 | F11: 100 | G11: 100
A12: Sales of goods and services | B12: N/A | C12: N/A | D12: N/A | E12: N/A | F12: N/A | G12: N/A
A13: All other revenues | B13: N/A | C13: N/A | D13: N/A | E13: N/A | F13: N/A | G13: N/A
A14: Cost of sales (direct expenses) | B14: 51.0A | C14: 24.9 | D14: 38 | E14: 41.5 | F14: 55.299999 | G14: 89
A15: Wages and benefits | B15: 14.0A | C15: 2.0999999 | D15: 6.3000002 | E15: 7.9000001 | F15: 16.5 | G15: 40.700001
A16: Purchases, materials and sub-contracts | B16: 37.8A | C16: 23.299999 | D16: 31 | E16: 34.299999 | F16: 39.700001 | G16: 89.599998
A17: Opening inventory | B17: 11.4A | C17: 13 | D17: 3.8 | E17: 8.5 | F17: 12.7 | G17: 67
A18: Closing inventory | B18: 12.1A | C18: 13.5 | D18: 3.0999999 | E18: 9.1000004 | F18: 13.6 | G18: 64.300003
A19: Operating expenses (indirect expenses) | B19: 42.8A | C19: 67.099998 | D19: 57.400002 | E19: 58 | F19: 37.099998 | G19: 100
A20: Labour and commissions | B20: 17.7A | C20: 11.9 | D20: 19.4 | E20: 23.6 | F20: 16.200001 | G20: 65.900002
A21: Amortization and depletion | B21: 3.0A | C21: 6 | D21: 4.9000001 | E21: 4.5999999 | F21: 2.3 | G21: 76.900002
A22: Repairs and maintenance | B22: 1.3A | C22: 1.6 | D22: 1.6 | E22: 1.6 | F22: 1.2 | G22: 72
A23: Utilities and telephone/telecommunication | B23: 1.5A | C23: 3.9000001 | D23: 2.7 | E23: 1.9 | F23: 1.2 | G23: 86.300003
A24: Rent | B24: 5.6A | C24: 7.5 | D24: 10 | E24: 7.5999999 | F24: 4.6999998 | G24: 73.599998
A25: Interest and bank charges | B25: 1.1A | C25: 4.4000001 | D25: 1.3 | E25: 2.5 | F25: 0.60000002 | G25: 48.400002
... A32: Net profit/loss | B32: 6.1A | C32: 7.9000001 | D32: 4.5999999 | E32: 0.5 | F32: 7.6999998 | G32: 100
A34: Financial ratios | B34: Averages
A35: Interest coverage ratio | B35: 6.5999999 | C35: 2.8 | D35: 4.5999999 | E35: 1.2 | F35: 13.5
A36: Gross margin (%) | B36: 49 | C36: 75.099998 | D36: 62 | E36: 58.5 | F36: 44.700001
A38: Profitable vs Non-profitable businesses | B38: (thousands of dollars)
A39: Profitable
A40: Percentage of businesses (%) | B40: 64.300003 | C40: N/A | D40: N/A | E40: N/A | F40: N/A
A41: Total revenue | B41: 666.2A | C41: 51.700001 | D41: 135.3 | E41: 441.70001 | F41: 1825.5
A42: Total expenses | B42: 572.2A | C42: 35.700001 | D42: 105.4 | E42: 377.60001 | F42: 1585.8
A43: Net profit | B43: 94.0A | C43: 16 | D43: 29.9 | E43: 64.099998 | F43: 239.8
A44: Non-Profitable
A45: Percentage of businesses (%) | B45: 35.700001 | C45: N/A | D45: N/A | E45: N/A | F45: N/A
A46: Total revenue | B46: 515.8A | C46: 47 | D46: 139.89999 | E46: 504 | F46: 1707.7
A47: Total expenses | B47: 579.8A | C47: 70.099998 | D47: 163.60001 | E47: 588 | F47: 1855.3
A48: Net loss | B48: -64.1A | C48: -23.1 | D48: -23.700001 | E48: -83.900002 | F48: -147.7
A50: Note: | B50: Balance sheet information is not available for all businesses and unincorporated businesses under the incorporation status.
A52: Profile
A53: Revenue range | B53: Annual revenues $30,000 - $5,000,000
...

Sheet NAICS$
A1: NAICS$ (2023)
B4: Whole industry (reliability) | C4: Bottom quartile (25%) | D4: Lower middle (25%) | E4: Upper middle (25%) | F4: Top quartile (25%) | G4: Percentage of businesses reporting
A6: Number of businesses | B6: 182
A7: Revenue range:
A8: Low Value ($000) | B8: 30 | C8: 30 | D8: 74 | E8: 214 | F8: 722
A9: High Value ($000) | B9: 5000 | C9: 74 | D9: 214 | E9: 722 | F9: 5000
A11: Revenues and expenses | B11: (thousands of dollars) - Averages
A12: Total revenue | B12: 612.4A | C12: 50.200001 | D12: 137.3 | E12: 467.79999 | F12: 1794.5 | G12: 100
A13: Sales of goods and services | B13: N/A | C13: N/A | D13: N/A | E13: N/A | F13: N/A | G13: N/A
A14: All other revenues | B14: N/A | C14: N/A | D14: N/A | E14: N/A | F14: N/A | G14: N/A
A15: Cost of sales (direct expenses) | B15: 312.6A | C15: 12.5 | D15: 52.099998 | E15: 194.10001 | F15: 991.5 | G15: 89
A16: Wages and benefits | B16: 85.8A | C16: 1 | D16: 8.6999998 | E16: 36.799999 | F16: 296.5 | G16: 40.700001
A17: Purchases, materials and sub-contracts | B17: 231.6A | C17: 11.7 | D17: 42.599998 | E17: 160.3 | F17: 711.70001 | G17: 89.599998
A18: Opening inventory | B18: 69.6A | C18: 6.5999999 | D18: 5.1999998 | E18: 39.700001 | F18: 227.10001 | G18: 67
A19: Closing inventory | B19: 74.4A | C19: 6.8000002 | D19: 4.3000002 | E19: 42.700001 | F19: 243.8 | G19: 64.300003
A20: Operating expenses (indirect expenses) | B20: 262.3A | C20: 33.700001 | D20: 78.900002 | E20: 271.29999 | F20: 665.40002 | G20: 100
A21: Labour and commissions | B21: 108.5A | C21: 6 | D21: 26.6 | E21: 110.5 | F21: 290.79999 | G21: 65.900002
A22: Amortization and depletion | B22: 18.3A | C22: 3 | D22: 6.8000002 | E22: 21.700001 | F22: 41.700001 | G22: 76.900002
A23: Repairs and maintenance | B23: 8.0A | C23: 0.80000001 | D23: 2.3 | E23: 7.6999998 | F23: 21.299999 | G23: 72
A24: Utilities and telephone/telecommunication | B24: 9.3A | C24: 2 | D24: 3.8 | E24: 9.1000004 | F24: 22.299999 | G24: 86.300003
A25: Rent | B25: 34.4A | C25: 3.7 | D25: 13.8 | E25: 35.700001 | F25: 84.400002 | G25: 73.599998
A26: Interest and bank charges | B26: 6.7A | C26: 2.2 | D26: 1.7 | E26: 11.8 | F26: 11 | G26: 48.400002
... A33: Net profit/loss | B33: 37.5A | C33: 4 | D33: 6.3000002 | E33: 2.3 | F33: 137.60001 | G33: 100
A35: Financial ratios | B35: Averages
A36: Interest coverage ratio | B36: 6.5999999 | C36: 2.8 | D36: 4.5999999 | E36: 1.2 | F36: 13.5
A37: Gross margin (%) | B37: 49 | C37: 75.099998 | D37: 62 | E37: 58.5 | F37: 44.700001
A39: Profitable vs Non-profitable businesses | B39: (thousands of dollars)
A40: Profitable
A41: Percentage of businesses (%) | B41: 64.300003 | C41: N/A | D41: N/A | E41: N/A | F41: N/A
A42: Total revenue | B42: 666.2A | C42: 51.700001 | D42: 135.3 | E42: 441.70001 | F42: 1825.5
A43: Total expenses | B43: 572.2A | C43: 35.700001 | D43: 105.4 | E43: 377.60001 | F43: 1585.8
A44: Net profit | B44: 94.0A | C44: 16 | D44: 29.9 | E44: 64.099998 | F44: 239.8
A45: Non-Profitable
A46: Percentage of businesses (%) | B46: 35.700001 | C46: N/A | D46: N/A | E46: N/A | F46: N/A
A47: Total revenue | B47: 515.8A | C47: 47 | D47: 139.89999 | E47: 504 | F47: 1707.7
A48: Total expenses | B48: 579.8A | C48: 70.099998 | D48: 163.60001 | E48: 588 | F48: 1855.3
A49: Net loss | B49: -64.1A | C49: -23.1 | D49: -23.700001 | E49: -83.900002 | F49: -147.7
A52: Note: | B52: Balance sheet information is not available for all businesses and unincorporated businesses under the incorporation status.
A54: Profile
A55: Revenue range | B55: Annual revenues $30,000 - $5,000,000
...
