Workbook

Sheet Cover
A1: Pawfect Pet Grooming - 2026
A3: Project | B3: This is a set of financial statement prepared for the Pet Grooming business to help with forecasting, budgeting, and overall financial analysis of a start-up business in Pet Care manufacturing and retaining.
A5: Contents
A6: Cover Page | B6: This page
A7: Net worth Statement | B7: Snapshot of financial health, comparing assets to liabilities.
A8: Family budget | B8: Monthly income allocation for expenses, savings, and financial goals.
A9: CFF | B9: Proforma Cash Flow Statement
A10: IS | B10: Proforma Income Statement(s) Including Comparisons to Industry Performance Data.
A11: BS | B11: Proforma Balance Sheet(s)
A12: Startup | B12: Startup expenses are entered here. Includes a Statement of Cash and Startup Income Statement and Balance Sheet.
A13: Marketing | B13: Marketing expense projection for 2026 and 2027
A14: Sales Projections | B14: Sales Projections for 2026 and 2027
A15: Assets | B15: Capital Purchases and Depreciation
A16: HR Exp | B16: Owner Drawings and Employee Expenses
A17: Financing | B17: Financing including investments, loans and lines of Credit
... A20: NAICS $ | B20: 2023 Industry Performance Data Sheet Unincorporated $
A22: LEGEND
A23: User input cell | B23: Fields that can be changed and reflected in the calculations
A24: Calculated Cells | B24: Theses cells are calculated and should not be changed
A25: Check calculations | B25: Calculations used to validate the spreadsheet. This can ignored and should note printed.
A26: Memo | B26: Memo field linked to original source
A27: Instructions | B27: Instructions are included throughout the template in the boxes shown in this colour

Sheet Family Budget
A1: Family Budget - 2025
B3: Category | C3: Husband's Amount | D3: Wife's Amount | E3: Total
B4: Income
B5: Salary | C5: 120000 | D5: 60000 | E5: =SUM(C5:D5) -> 180000
B6: Bonus | C6: 10000 | D6: 3000 | E6: =SUM(C6:D6) -> 13000
B7: Total Income | C7: =SUM(C5:C6) -> 130000 | D7: =SUM(D5:D6) -> 63000 | E7: =SUM(C7:D7) -> 193000
B8: Expenses
B9: Mortgage | C9: 46512 | D9: 0 | E9: =SUM(C9:D9) -> 46512
B10: Utilities | C10: 0 | D10: 3600 | E10: =SUM(C10:D10) -> 3600
B11: Car Loan | C11: 3600 | D11: 2400 | E11: =SUM(C11:D11) -> 6000
B12: Car Insurance | C12: 1800 | D12: 1200 | E12: =SUM(C12:D12) -> 3000
B13: Groceries | C13: 4800 | D13: 3600 | E13: =SUM(C13:D13) -> 8400
B14: Dining Out | C14: 2400 | D14: 1800 | E14: =SUM(C14:D14) -> 4200
B15: Entertainment | C15: 1800 | D15: 1200 | E15: =SUM(C15:D15) -> 3000
B16: Clothing | C16: 1200 | D16: 1200 | E16: =SUM(C16:D16) -> 2400
B17: Personal Care | C17: 600 | D17: 900 | E17: =SUM(C17:D17) -> 1500
B18: Gym Membership | C18: 200 | D18: 200 | E18: =SUM(C18:D18) -> 400
B19: Cell Phone | C19: 500 | D19: 500 | E19: =SUM(C19:D19) -> 1000
B20: Internet | C20: 260 | D20: 0 | E20: =SUM(C20:D20) -> 260
... B23: Credit Card Payment | C23: 34800 | D23: 15600 | E23: =SUM(C23:D23) -> 50400
B24: Total Expenses | C24: =SUM(C9:C23) -> 100872 | D24: =SUM(D9:D23) -> 33760 | E24: =SUM(C24:D24) -> 134632
B25: Savings
B26: TFSA | C26: 3000 | D26: 3600 | E26: =SUM(C26:D26) -> 6600
B27: RRSP | C27: 6000 | D27: 6000 | E27: =SUM(C27:D27) -> 12000
B28: Emergency Fund | C28: 2400 | D28: 1200 | E28: =SUM(C28:D28) -> 3600
B29: Investments | C29: 12500 | D29: 1800 | E29: =SUM(C29:D29) -> 14300
B30: Total Savings | C30: =SUM(C26:C29) -> 23900 | D30: =SUM(D26:D29) -> 12600 | E30: =SUM(C30:D30) -> 36500
B31: Net Cash Flow | C31: =C7-C24-C30 -> 5228 | D31: =D7-D24-D30 -> 16640 | E31: =SUM(C31:D31) -> 21868
B33: Notes:
B34: 1. After tax income has been used for budgeting. 2. All the expense and investments numbers includes additional charges and tax paid.

Sheet Networth Stmt
A1: Net worth Statement
B3: Category | D3: Husband | E3: Wife | F3: Total
B4: Current Assets
C5: Bank Savings | D5: 15000 | E5: 10000 | F5: =SUM(D5:E5) -> 25000
C6: Stocks | D6: 25000 | E6: 15000 | F6: =SUM(D6:E6) -> 40000
C7: Mutual Funds | D7: 20000 | E7: 10000 | F7: =SUM(D7:E7) -> 30000
C8: Total Current Assets | D8: =SUM(D5:D7) -> 60000 | E8: =SUM(E5:E7) -> 35000 | F8: =SUM(D8:E8) -> 95000
B9: Long-term Assets
C10: TFSA | D10: 30000 | E10: 20000 | F10: =SUM(D10:E10) -> 50000
C11: RRSP | D11: 50000 | E11: 25000 | F11: =SUM(D11:E11) -> 75000
C12: Primary Residence | D12: 800000 | E12: 0 | F12: =SUM(D12:E12) -> 800000
C13: Car | D13: 25000 | E13: 15000 | F13: =SUM(D13:E13) -> 40000
C14: Furniture | D14: 10000 | E14: 8000 | F14: =SUM(D14:E14) -> 18000
C15: Jewellery | D15: 2000 | E15: 10000 | F15: =SUM(D15:E15) -> 12000
C16: Total Long-term Assets | D16: =SUM(D10:D15) -> 917000 | E16: =SUM(E10:E15) -> 78000 | F16: =SUM(D16:E16) -> 995000
C17: Total Assets | D17: =SUM(D8+D16) -> 977000 | E17: =SUM(E8+E16) -> 113000 | F17: =SUM(D17:E17) -> 1090000
B18: Current Liabilities
C19: Credit Card Debt - CIBC Aventura | D19: 1900 | E19: 0 | F19: =SUM(D19:E19) -> 1900
C20: Credit Card Debt - Amex Gold | D20: 1000 | E20: 1300 | F20: =SUM(D20:E20) -> 2300
C21: Total Current Liabilities | D21: =SUM(D19:D20) -> 2900 | E21: =SUM(E19:E20) -> 1300 | F21: =SUM(D21:E21) -> 4200
B22: Long-term Liabilities
C23: Mortgage | D23: 500000 | E23: 0 | F23: =SUM(D23:E23) -> 500000
C24: Car Loan | D24: 15000 | E24: 8000 | F24: =SUM(D24:E24) -> 23000
C25: Student Loans | D25: 10000 | E25: 5000 | F25: =SUM(D25:E25) -> 15000
C26: Total Long-term Liabilities | D26: =SUM(D23:D25) -> 525000 | E26: =SUM(E23:E25) -> 13000 | F26: =SUM(D26:E26) -> 538000
C27: Total Liabilities | D27: =SUM(D21+D26) -> 527900 | E27: =SUM(E21+E26) -> 14300 | F27: =SUM(D27:E27) -> 542200
C28: Net Worth | D28: =SUM(D17-D27) -> 449100 | E28: =SUM(E17-E27) -> 98700 | F28: =SUM(D28:E28) -> 547800
B31: Note:
B32: 1. Both partners have maximized their TFSA contributions based on their age, with the husband having a higher amount due to more years of eligibility. 2. The RRSP contributions reflect the higher income of the husband, who has likely been able to contribute more over the years. 3. Home is owned by husband and he is responsible to make monthly payments.
B40: Capital Investment
B41: Considering their liquid assets and annual savings capacity, the couple could potentially afford to invest $50,000 in a business venture without significantly impacting their current lifestyle or financial stability. This amount would allow them to maintain an emergency fund and continue meeting their regular expenses and savings goals.

Sheet CFF
B1: Pawfect Pet Grooming
B2: Proforma Cash Flow Statement
B3: January 2026 To December 2027
C5: 46047 | D5: 46078 | E5: 46106 | F5: 46137 | G5: 46167 | H5: 46198 | I5: 46228 | J5: 46259 | K5: 46290 | L5: 46320 | M5: 46351 | N5: 46381 | O5: Total
A6: Notes | B6: Inflows
A7: Sales | B7: Online Bookings - Cash | C7: =Sales!B30 -> 1512.9 | D7: =Sales!C30 -> 1512.9 | E7: =Sales!D30 -> 2420.64 | F7: =Sales!E30 -> 3328.38 | G7: =Sales!F30 -> 4236.12 | H7: =Sales!G30 -> 3025.8 | I7: =Sales!H30 -> 2118.06 | J7: =Sales!I30 -> 2420.64 | ... O7: =Sales!N30 -> 30258
A8: Sales | B8: Online Bookings - Credit Card | C8: =Sales!B31 -> 3530.1 | D8: =Sales!C31 -> 3530.1 | E8: =Sales!D31 -> 5648.16 | F8: =Sales!E31 -> 7766.22 | G8: =Sales!F31 -> 9884.28 | H8: =Sales!G31 -> 7060.2 | I8: =Sales!H31 -> 4942.14 | J8: =Sales!I31 -> 5648.16 | ... O8: =Sales!N31 -> 70602
A9: Sales | B9: Total Online Bookings | C9: =Sales!B29 -> 5043 | D9: =Sales!C29 -> 5043 | E9: =Sales!D29 -> 8068.8 | F9: =Sales!E29 -> 11094.6 | G9: =Sales!F29 -> 14120.4 | H9: =Sales!G29 -> 10086 | I9: =Sales!H29 -> 7060.2 | J9: =Sales!I29 -> 8068.8 | ... O9: =Sales!N29 -> 100860
A10: Sales | B10: Phone Bookings - Cash | C10: =Sales!B33 -> 2017.2 | D10: =Sales!C33 -> 2017.2 | E10: =Sales!D33 -> 3227.52 | F10: =Sales!E33 -> 4437.84 | G10: =Sales!F33 -> 5648.16 | H10: =Sales!G33 -> 4034.4 | I10: =Sales!H33 -> 2824.08 | J10: =Sales!I33 -> 3227.52 | ... O10: =Sales!N33 -> 40344
A11: Sales | B11: Phone Bookings - Credit Card | C11: =Sales!B34 -> 1344.8 | D11: =Sales!C34 -> 1344.8 | E11: =Sales!D34 -> 2151.68 | F11: =Sales!E34 -> 2958.56 | G11: =Sales!F34 -> 3765.44 | H11: =Sales!G34 -> 2689.6 | I11: =Sales!H34 -> 1882.72 | J11: =Sales!I34 -> 2151.68 | ... O11: =Sales!N34 -> 26896
A12: Sales | B12: Total Phone Bookings | C12: =Sales!B32 -> 3362 | D12: =Sales!C32 -> 3362 | E12: =Sales!D32 -> 5379.2 | F12: =Sales!E32 -> 7396.4 | G12: =Sales!F32 -> 9413.6 | H12: =Sales!G32 -> 6724 | I12: =Sales!H32 -> 4706.8 | J12: =Sales!I32 -> 5379.2 | ... O12: =Sales!N32 -> 67240
A13: Sales | B13: Total Sales | C13: =Sales!B35 -> 8405 | D13: =Sales!C35 -> 8405 | E13: =Sales!D35 -> 13448 | F13: =Sales!E35 -> 18491 | G13: =Sales!F35 -> 23534 | H13: =Sales!G35 -> 16810 | I13: =Sales!H35 -> 11767 | J13: =Sales!I35 -> 13448 | ... O13: =Sales!N35 -> 168100
A14: Startup | B14: Owner's Investment | C14: =Startup!B39 -> 50000 | D14: 0 | E14: 0 | F14: 0 | G14: 0 | H14: 0 | I14: 0 | J14: 0 | K14: 0 | L14: 0 | M14: 0 | N14: 0 | O14: =SUM(C14:N14) -> 50000
A15: Startup/ Financing | B15: Loan | C15: 40000 | D15: 0 | E15: 0 | F15: 0 | G15: 0 | H15: 0 | I15: 0 | J15: 0 | K15: 0 | L15: 0 | M15: 0 | N15: 0 | O15: =SUM(C15:N15) -> 40000
B16: Total Inflows | C16: =C13+C14+C15 -> 98405 | D16: =D13+D14 -> 8405 | E16: =E13+E14 -> 13448 | F16: =F13+F14 -> 18491 | G16: =G13+G14 -> 23534 | H16: =H13+H14 -> 16810 | I16: =I13+I14 -> 11767 | J16: =J13+J14 -> 13448 | K16: =K13+K14 -> 20172 | ... O16: =O13+O14 -> 218100
C18: 46047 | D18: 46078 | E18: 46106 | F18: 46137 | G18: 46167 | H18: 46198 | I18: 46228 | J18: 46259 | K18: 46290 | L18: 46320 | M18: 46351 | N18: 46381 | O18: Total
A19: Notes | B19: Outflows
A20: Startup | B20: Startup Expenses | C20: =Startup!C22 -> 58000 | D20: 0 | E20: 0 | F20: 0 | G20: 0 | H20: 0 | I20: 0 | J20: 0 | K20: 0 | L20: 0 | M20: 0 | N20: 0 | O20: =SUM(C20:N20) -> 58000
A21: HR | B21: Groomer Wages | C21: ='HR Exp'!B21+'HR Exp'!B24 -> 3520 | D21: ='HR Exp'!C21+'HR Exp'!C24 -> 3520 | E21: ='HR Exp'!D21+'HR Exp'!D24 -> 3520 | F21: ='HR Exp'!E21+'HR Exp'!E24 -> 3520 | G21: ='HR Exp'!F21+'HR Exp'!F24 -> 4600 | H21: ='HR Exp'!G21+'HR Exp'!G24 -> 4600 | I21: ='HR Exp'!H21+'HR Exp'!H24 -> 4060 | J21: ='HR Exp'!I21+'HR Exp'!I24 -> 4600 | ... N21: ='HR Exp'!M21+'HR Exp'!M24 -> 3520 | O21: =SUM(C21:N21) -> 50520
A22: HR | B22: Payroll Taxes & Benefits | C22: ='HR Exp'!B22+'HR Exp'!B25 -> 739.2 | D22: ='HR Exp'!C22+'HR Exp'!C25 -> 739.2 | E22: ='HR Exp'!D22+'HR Exp'!D25 -> 739.2 | F22: ='HR Exp'!E22+'HR Exp'!E25 -> 739.2 | G22: ='HR Exp'!F22+'HR Exp'!F25 -> 933.6 | H22: ='HR Exp'!G22+'HR Exp'!G25 -> 933.6 | I22: ='HR Exp'!H22+'HR Exp'!H25 -> 836.4 | J22: ='HR Exp'!I22+'HR Exp'!I25 -> 933.6 | ... N22: ='HR Exp'!M22+'HR Exp'!M25 -> 739.2 | O22: =SUM(C22:N22) -> 10360.8
A23: OPs | B23: Grooming Supplies | C23: 840 | D23: 840 | E23: 1345 | F23: 1849 | G23: 2353 | H23: 1681 | I23: 1177 | J23: 1345 | K23: 2017 | L23: 2185 | M23: 1009 | N23: 168 | O23: =SUM(C23:N23) -> 16809
A24: Ops | B24: Van Fuel | C24: 300 | D24: 300 | E24: 380 | F24: 460 | G24: 540 | H24: 420 | I24: 340 | J24: 380 | K24: 460 | L24: 500 | M24: 340 | N24: 180 | O24: =SUM(C24:N24) -> 4600
A25: Ops | B25: Vehicle Maintenance | C25: 200 | D25: 200 | E25: 200 | F25: 200 | G25: 200 | H25: 200 | I25: 200 | J25: 200 | K25: 200 | L25: 200 | M25: 200 | N25: 200 | O25: =SUM(C25:N25) -> 2400
A26: Ops | B26: Repairs and Maintenance | C26: ='Other Exp'!B6 -> 325 | D26: ='Other Exp'!C6 -> 325 | E26: ='Other Exp'!D6 -> 325 | F26: ='Other Exp'!E6 -> 325 | G26: ='Other Exp'!F6 -> 325 | H26: ='Other Exp'!G6 -> 325 | I26: ='Other Exp'!H6 -> 325 | J26: ='Other Exp'!I6 -> 325 | ... N26: ='Other Exp'!M6 -> 325 | O26: =SUM(C26:N26) -> 3900
A27: Ops | B27: Utilities and Telephone | C27: ='Other Exp'!B7 -> 350 | D27: ='Other Exp'!C7 -> 350 | E27: ='Other Exp'!D7 -> 350 | F27: ='Other Exp'!E7 -> 350 | G27: ='Other Exp'!F7 -> 350 | H27: ='Other Exp'!G7 -> 350 | I27: ='Other Exp'!H7 -> 350 | J27: ='Other Exp'!I7 -> 350 | ... N27: ='Other Exp'!M7 -> 350 | O27: =SUM(C27:N27) -> 4200
A28: Markt. | B28: Marketing & Advertising | C28: =Marketing!B31+Marketing!B38+Marketing!B13 -> 20822.4 | D28: =Marketing!C13 -> 672.4 | E28: =Marketing!D13 -> 1075.84 | F28: =Marketing!E13 -> 1479.28 | G28: =Marketing!F13 -> 1882.72 | H28: =Marketing!G13 -> 1344.8 | I28: =Marketing!H13 -> 941.36 | J28: =Marketing!I13 -> 1075.84 | K28: =Marketing!J13 -> 1613.76 | ... N28: =Marketing!M13 -> 134.48 | O28: =SUM(C28:N28) -> 33598
A29: Ops | B29: Delivery Fees | C29: ='Other Exp'!B8 -> 300 | D29: ='Other Exp'!C8 -> 300 | E29: ='Other Exp'!D8 -> 300 | F29: ='Other Exp'!E8 -> 300 | G29: ='Other Exp'!F8 -> 300 | H29: ='Other Exp'!G8 -> 300 | I29: ='Other Exp'!H8 -> 300 | J29: ='Other Exp'!I8 -> 300 | ... N29: ='Other Exp'!M8 -> 300 | O29: =SUM(C29:N29) -> 3600
A30: Ops | B30: Auto Insurance | C30: 350 | D30: 350 | E30: 350 | F30: 350 | G30: 350 | H30: 350 | I30: 350 | J30: 350 | K30: 350 | L30: 350 | M30: 350 | N30: 350 | O30: =SUM(C30:N30) -> 4200
B31: Liability Insurance | C31: 450 | D31: 450 | E31: 450 | F31: 450 | G31: 450 | H31: 450 | I31: 450 | J31: 450 | K31: 450 | L31: 450 | M31: 450 | N31: 450 | O31: =SUM(C31:N31) -> 5400
A32: Ops | B32: Bank Charges | C32: ='Other Exp'!B9 -> 40 | D32: ='Other Exp'!C9 -> 40 | E32: ='Other Exp'!D9 -> 40 | F32: ='Other Exp'!E9 -> 40 | G32: ='Other Exp'!F9 -> 40 | H32: ='Other Exp'!G9 -> 40 | I32: ='Other Exp'!H9 -> 40 | J32: ='Other Exp'!I9 -> 40 | ... N32: ='Other Exp'!M9 -> 40 | O32: =SUM(C32:N32) -> 480
A33: Ops | B33: Miscellaneous Expenses | C33: ='Other Exp'!B10 -> 100 | D33: ='Other Exp'!C10 -> 100 | E33: ='Other Exp'!D10 -> 100 | F33: ='Other Exp'!E10 -> 100 | G33: ='Other Exp'!F10 -> 100 | H33: ='Other Exp'!G10 -> 100 | I33: ='Other Exp'!H10 -> 100 | J33: ='Other Exp'!I10 -> 100 | ... N33: ='Other Exp'!M10 -> 100 | O33: =SUM(C33:N33) -> 1200
A34: Ops | B34: Credit Card Processing Fees | C34: =Financing!$B$3*(Sales!B34+Sales!B31) -> 60.93625 | D34: =Financing!$B$3*(Sales!C34+Sales!C31) -> 60.93625 | E34: =Financing!$B$3*(Sales!D34+Sales!D31) -> 97.498 | F34: =Financing!$B$3*(Sales!E34+Sales!E31) -> 134.05975 | G34: =Financing!$B$3*(Sales!F34+Sales!F31) -> 170.6215 | H34: =Financing!$B$3*(Sales!G34+Sales!G31) -> 121.8725 | I34: =Financing!$B$3*(Sales!H34+Sales!H31) -> 85.31075 | J34: =Financing!$B$3*(Sales!I34+Sales!I31) -> 97.498 | ... N34: =Financing!$B$3*(Sales!M34+Sales!M31) -> 12.18725 | O34: =SUM(C34:N34) -> 1218.725
B35: Total Operating Expenses | C35: =SUM(C20:C34) -> 86397.536 | D35: =SUM(D20:D34) -> 8247.5363 | E35: =SUM(E20:E34) -> 9272.538 | F35: =SUM(F20:F34) -> 10296.54 | G35: =SUM(G20:G34) -> 12594.941 | H35: =SUM(H20:H34) -> 11216.273 | I35: =SUM(I20:I34) -> 9555.0708 | J35: =SUM(J20:J34) -> 10546.938 | ... N35: =SUM(N20:N34) -> 6868.8672 | O35: =SUM(C35:N35) -> 200486.53
A36: Financing | B36: Van Loan Principal | C36: =Financing!B26 -> 0 | D36: =Financing!C26 -> 558.71461 | E36: =Financing!D26 -> 561.97378 | F36: =Financing!E26 -> 565.25196 | G36: =Financing!F26 -> 568.54926 | H36: =Financing!G26 -> 571.8658 | I36: =Financing!H26 -> 575.20168 | J36: =Financing!I26 -> 578.55702 | ... N36: =Financing!M26 -> 592.17527 | O36: =SUM(C36:N36) -> 6328.2888
A37: Financing | B37: Van Loan Interest | C37: =Financing!B25 -> 0 | D37: =Financing!C25 -> 233.33333 | E37: =Financing!D25 -> 230.07416 | F37: =Financing!E25 -> 226.79598 | G37: =Financing!F25 -> 223.49868 | H37: =Financing!G25 -> 220.18214 | I37: =Financing!H25 -> 216.84626 | J37: =Financing!I25 -> 213.49092 | ... N37: =Financing!M25 -> 199.87267 | O37: =SUM(C37:N37) -> 2384.2385
A38: HR | B38: Owner's Drawings | C38: 0 | D38: 0 | E38: 0 | F38: ='HR Exp'!$B$4 -> 3000 | G38: ='HR Exp'!$B$4 -> 3000 | H38: ='HR Exp'!$B$4 -> 3000 | I38: ='HR Exp'!$B$4 -> 3000 | J38: ='HR Exp'!$B$4 -> 3000 | K38: ='HR Exp'!$B$4 -> 3000 | L38: ='HR Exp'!$B$4 -> 3000 | M38: ='HR Exp'!$B$4 -> 3000 | N38: ='HR Exp'!$B$4 -> 3000 | O38: =SUM(C38:N38) -> 27000
A39: Financing | B39: Total Financing Outflows | C39: =SUM(C36:C38) -> 0 | D39: =SUM(D36:D38) -> 792.04794 | E39: =SUM(E36:E38) -> 792.04794 | F39: =SUM(F36:F38) -> 3792.0479 | G39: =SUM(G36:G38) -> 3792.0479 | H39: =SUM(H36:H38) -> 3792.0479 | I39: =SUM(I36:I38) -> 3792.0479 | J39: =SUM(J36:J38) -> 3792.0479 | ... N39: =SUM(N36:N38) -> 3792.0479 | O39: =SUM(C39:N39) -> 35712.527
B40: Total Outflows | C40: =C35+C39 -> 86397.536 | D40: =D35+D39 -> 9039.5842 | E40: =E35+E39 -> 10064.586 | F40: =F35+F39 -> 14088.588 | G40: =G35+G39 -> 16386.989 | H40: =H35+H39 -> 15008.32 | I40: =I35+I39 -> 13347.119 | J40: =J35+J39 -> 14338.986 | ... N40: =N35+N39 -> 10660.915 | O40: =SUM(C40:N40) -> 236199.05 | Q40: =SUM(C40:E40) -> 105501.71
B42: Reconciliation
B43: Beginning Cash on hand | C43: 0 | D43: =C49 -> 12007.464 | E43: =D49 -> 11372.88 | F43: =E49 -> 14756.294 | G43: =F49 -> 19158.706 | H43: =G49 -> 26305.716 | I43: =H49 -> 28107.396 | J43: =I49 -> 26527.277 | K43: =J49 -> 25636.291 | ... N43: =M49 -> 30880.863 | O43: =SUM(C43:N43) -> 258710.84
...

Sheet IS
B1: Pawfect Pet Grooming
B2: Proforma Income Statement
B3: January 2026 To December 2027
C5: 2026 | E5: 2027
B6: Category | C6: Amount ($) | D6: % of Sales | E6: Amount ($) | F6: % of Sales | G6: Industry Benchmark % | H6: Notes
B7: Sales
B8: Online Bookings | C8: =Sales!C11 -> 100860 | D8: =C8/$C$10 -> 0.6 | E8: =Sales!N41 -> 186591 | F8: =E8/$E$10 -> 0.6
B9: Phone Bookings | C9: =Sales!C12 -> 67240 | D9: =C9/$C$10 -> 0.4 | E9: =Sales!N44 -> 124394 | F9: =E9/$E$10 -> 0.4
B10: Total Sales | C10: 168100 | D10: =C10/$C$10 -> 1 | E10: =Sales!N47 -> 310985 | F10: =E10/$E$10 -> 1 | G10: ='NAICS%'!E10% -> 1 | H10: Total Revenue
B12: Cost of Goods Sold
B13: Wages & Benefits | C13: =CFF!O21+CFF!O22 -> 60880.8 | D13: =C13/$C$10 -> 0.36217014 | E13: ='HR Exp'!N35 -> 121761.6 | F13: =E13/$E$10 -> 0.39153528 | G13: ='NAICS%'!E14% -> 0.045 | H13: Wages and Benefits
B14: Grooming Supplies | C14: =CFF!O23 -> 16809 | D14: =C14/$C$10 -> 0.099994051 | E14: =CFF!O70 -> 16809 | F14: =E14/$E$10 -> 0.054050838 | G14: ='NAICS%'!E15% -> 0.11 | H14: Purchases, Materials, and Sub-contracts
B15: Van Fuel | C15: =CFF!O24 -> 4600 | D15: =C15/$C$10 -> 0.027364664 | E15: =CFF!O71 -> 4600 | F15: =E15/$E$10 -> 0.01479171 | H15: Part of service delivery costs
B16: Total COGS | C16: =SUM(C13:C15) -> 82289.8 | D16: =C16/$C$10 -> 0.48952885 | E16: =SUM(E13:E15) -> 143170.6 | F16: =E16/$E$10 -> 0.46037783 | G16: ='NAICS%'!E13% -> 0.154 | H16: Cost of sales (direct expenses)
B18: Gross Profit | C18: =C10-C16 -> 85810.2 | D18: =C18/$C$10 -> 0.51047115 | E18: =E10-E16 -> 167814.4 | F18: =E18/$E$10 -> 0.53962217 | G18: ='NAICS%'!E36% -> 0.84599998
B20: Operating expenses
B21: Depreciation | C21: =Assets!E8 -> 12217 | D21: =C21/$C$10 -> 0.072676978 | E21: =Assets!C14 -> 12217 | F21: =E21/$E$10 -> 0.039284853 | G21: ='NAICS%'!E20% -> 0.029000001 | H21: Amortization and depletion
B22: Fuel Charge | C22: =CFF!O24 -> 4600 | D22: =C22/$C$10 -> 0.027364664 | E22: =CFF!O24 -> 4600 | F22: =E22/$E$10 -> 0.01479171 | H22: Repairs and maintenance
B23: Repairs and Maintenance | C23: =CFF!O25 -> 2400 | D23: =C23/$C$10 -> 0.014277216 | E23: =CFF!O25 -> 2400 | F23: =E23/$E$10 -> 0.007717414 | G23: ='NAICS%'!E21% -> 0.020999999 | H23: Repairs and maintenance
B24: Utilities and Telephone | C24: =CFF!O27 -> 4200 | D24: =C24/$C$10 -> 0.024985128 | E24: =CFF!O27 -> 4200 | F24: =E24/$E$10 -> 0.013505475 | G24: ='NAICS%'!E22% -> 0.032 | H24: Utilities and telephone/telecommunication
B25: Delivery Fees | C25: =CFF!O29 -> 3600 | D25: =C25/$C$10 -> 0.021415824 | E25: =CFF!O29 -> 3600 | F25: =E25/$E$10 -> 0.011576121 | G25: ='NAICS%'!E27% -> 0.001 | H25: Delivery, shipping and warehouse expenses
B26: Insurance | C26: =CFF!O30 -> 4200 | D26: =C26/$C$10 -> 0.024985128 | E26: =CFF!O78+CFF!O77 -> 9600 | F26: =E26/$E$10 -> 0.030869656 | G26: ='NAICS%'!E28% -> 0.015 | H26: Insurance
B27: Interest & Bank Charges | C27: =SUM(C28:C30) -> 4082.9635 | D27: =C27/$C$10 -> 0.024288897 | E27: =SUM(E28:E30) -> 4857.8256 | F27: =E27/$E$10 -> 0.015620771 | G27: ='NAICS%'!E24% -> 0.012 | H27: Interest and bank charges
B28: Credit Card Processing Fees | C28: =CFF!O34 -> 1218.725 | E28: =CFF!O81 -> 2254.6413
B29: Interest Expense | C29: =Financing!N25 -> 2384.2385 | E29: =Financing!N33 -> 2123.1844 | H29: Interest and bank charges
B30: Bank Charges | C30: =CFF!O32 -> 480 | E30: =CFF!O79 -> 480 | H30: Interest and bank charges
B31: Marketing & Advertising | C31: =CFF!O28 -> 33598 | D31: =C31/$C$10 -> 0.19986913 | E31: =CFF!O75 -> 45028.8 | F31: =E31/$E$10 -> 0.14479412 | G31: ='NAICS%'!E26% -> 0.015 | H31: Advertising and promotion
B32: Miscellaneous Expenses | C32: =CFF!O33 -> 1200 | D32: =C32/$C$10 -> 0.007138608 | E32: =CFF!Q33 -> 0 | F32: =E32/$C$10 -> 0 | G32: ='NAICS%'!E29% -> 0.148 | H32: Other Expenses
B33: Total Operating Expenses | C33: =SUM(C21:C27,C31:C32) -> 70097.964 | D33: =SUM(D21:D27,D31:D32) -> 0.41700157 | E33: =SUM(E21:E27,E31:E32) -> 86503.626 | F33: =SUM(F21:F27,F31:F32) -> 0.27816012 | G33: ='NAICS%'!E18% -> 0.58799999 | H33: Total expenses
B35: Total Operating Profit Before Taxes | C35: =C18-C33 -> 15712.236 | D35: =C35/C10 -> 0.09346958 | E35: =E18-E33 -> 81310.774 | F35: =E35/E10 -> 0.26146205 | G35: ='NAICS%'!E31% -> 0.25799999 | H35: Net profit/loss

Sheet BS
B1: Pawfect Pet Grooming
B2: Proforma Balance Sheet as of Dec 31, 2026 &2027
D4: as of December 31, 2026 | E4: as of December 31, 2027
C5: Assets
C6: Current Assets
C7: Cash on hand | D7: =CFF!N49 -> 21900.948 | E7: =CFF!N97 -> 73977.123
C8: Inventories | D8: =CFF!N23 -> 168 | E8: =CFF!N70 -> 168
C9: A/R | D9: 0 | E9: 0
C10: Total Current Assets | D10: =SUM(D7:D9) -> 22068.948 | E10: =SUM(E7:E9) -> 74145.123
C12: Long Term Assets
C13: LT Assets Original Value | D13: =Assets!B8 -> 62200 | E13: =Assets!C13 -> 49983
C14: Less: Accumulated Depreciation | D14: =Assets!E8 -> 12217 | E14: =Assets!C14 -> 12217
C15: Total Net LT Assets | D15: =D13-D14 -> 49983 | E15: =E13-E14 -> 37766
C17: Total Assets | D17: =D10+D15 -> 72051.948 | E17: =E10+E15 -> 111911.12
C19: Liabilities and Equity
C20: Current Liabilities
C21: Line of Credit | D21: 0 | E21: 0
C22: Loan | D22: 0 | E22: 0
C23: Long term Liabilities | D23: =Financing!M27 -> 33671.711 | E23: =Financing!M35 -> 26290.32
C25: Total Liabilities | D25: =SUM(D21:D23) -> 33671.711 | E25: =SUM(E21:E23) -> 26290.32
C28: Equity
C29: Opening owner's Equity | D29: 4668 | E29: 48157.357
C30: Add profit (Less Loss) | D30: =IS!C35 -> 15712.236 | E30: =IS!E35 -> 81310.774
C31: Add Owner Inflow | D31: =Startup!B39 -> 50000 | E31: =CFF!C60 -> 0
C32: Add Capital Increase | D32: 0 | E32: 0
C33: Less Owner's Drawings | D33: =CFF!O38 -> 27000 | E33: =CFF!O85 -> 36066
C34: Owner's Equity | D34: =SUM(D29:D32)-D33 -> 43380.236 | E34: =SUM(E29:E32)-E33 -> 93402.131
C36: Total Liabilities + Equity | D36: =D25+D34 -> 77051.948 | E36: =E25+E34 -> 119692.45

Sheet Startup
A1: Pawfect Pet Grooming Shop
A2: Startup Expenses
A4: Category | B4: Description | C4: Amount ($) | D4: Notes
A5: Business Registration & Licensing | B5: Business registration fees, permits, and licenses | C5: 1500 | D5: Includes commercial vehicle registration and local permits.
A6: Mobile Van & Equipment | B6: Van purchase/down payment | C6: 10000 | D6: Down payment for mobile grooming van.
B7: Van customization (interior setup) | C7: 15000 | D7: Includes grooming tables, dryers, water tanks, and plumbing.
B8: Grooming equipment | C8: 5000 | D8: Includes clippers, scissors, brushes, nail trimmers, etc.
B9: Initial inventory | C9: 3000 | D9: Shampoos, conditioners, cleaning supplies for the first month.
A10: Technology & Software | B10: Scheduling and booking software | C10: 1200 | D10: Annual subscription for a pet grooming scheduling app.
B11: Website development | C11: 3000 | D11: User-friendly website with online booking capabilities.
B12: Mobile app development | C12: 5000 | D12: Custom app for customer bookings and service tracking.
A13: Marketing & Branding | B13: Logo design | C13: =Marketing!B27 -> 750 | D13: Professional logo design to reflect branding strategy.
B14: Vehicle wrap design and application | C14: =Marketing!B28 -> 3500 | D14: Branding on the mobile van to serve as a moving advertisement.
B15: Website Development | C15: =Marketing!B29 -> 3000 | D15: Initial setup of Instagram, Facebook, and TikTok accounts with content creation.
B16: Initial advertising campaign | C16: =Marketing!B30 -> 2500 | D16: Digital ads targeting local pet owners in the Kitchener-Waterloo region.
A17: Professional Services | B17: Legal fees | C17: 1000 | D17: Covering contracts and compliance with local regulations.
B18: Accounting fees | C18: 750 | D18: Assistance with setting up accounting systems and tax planning.
A19: Insurance | B19: Auto insurance | C19: 350 | D19: Covers liability insurance for mobile operations and equipment.
B20: Liability Insurance | C20: 450 | D20: Covers liability insurance for any injuries or accident on business.
A21: Miscellaneous Expenses | B21: Miscellaneous | C21: 2000 | D21: Unforeseen costs during startup (e.g., repairs or additional supplies).
A22: Total Startup Cost | C22: =SUM(C5:C21) -> 58000
A23: Notes:
A24: 1. The mobile grooming van's significant portion of the startup costs allocated to its down payment and remodelling. 2. Inventory includes initial supplies and products needed for the first month of operations. 3. Marketing costs are allocated for initial brand awareness and customer acquisition. 4.Professional fees cover legal and accounting services needed for business setup. 5. A miscellaneous expense category is included to account for unforeseen costs.
A35: Pawfect Pet Grooming
A36: Startup Cash Requirements
A38: Inflows
A39: Owner Investment | B39: 50000
A40: Outflow
A41: Startup + initial 3 Month expenses | B41: =SUM(CFF!C40:E40) -> 105501.71
A42: Investment Required | B42: =B41-B39 -> 55501.706
A44: Business Registration & Licensing | B44: 1500 | C44: Includes commercial vehicle registration and local permits.
A45: Mobile Van & Equipment | B45: =SUM(C6:C9) -> 33000
A46: Technology & Software | B46: =SUM(C10:C12) -> 9200
A47: Marketing & Branding | B47: =SUM(C13:C16) -> 9750
A48: Professional Services | B48: =SUM(C17:C18) -> 1750
A49: Insurance | B49: =SUM(C19:C20) -> 800
A50: Miscellaneous Expenses | B50: =C21 -> 2000
B51: =SUM(B44:B50) -> 58000

Sheet Sales
A1: Sales Projections
A3: Forecast: 2026-2027
A4: 2025 | B4: 168100
A5: Growth rate for 2nd Year | B5: 0.85
A6: 2026 | B6: =B4*(1+B5) -> 310985
A8: Forecasted Sales & Payment Mix
A9: Sales Channels | B9: Year 1 | D9: Year 2
B10: % of Sales Mix | C10: Sales in $ | D10: Sales in $
A11: Online Bookings | B11: 0.6 | C11: =$B$4*(B11) -> 100860 | D11: =$B$6*(B11) -> 186591
A12: Phone Booking | B12: 0.4 | C12: =$B$4*(B12) -> 67240 | D12: =$B$6*(B12) -> 124394
A14: Sales Channels | B14: Payment Methods | D14: Total
B15: Cash | C15: Credit/Debit Card
A16: Online Bookings | B16: 0.3 | C16: 0.7 | D16: =SUM(B16:C16) -> 1 | E16: Because of Easy payment system on website
A17: Phone Booking | B17: 0.6 | C17: 0.4 | D17: =SUM(B17:C17) -> 1
A20: Monthly Seasonality of Business
A21: Month | B21: Jan | C21: Feb | D21: Mar | E21: Apr | F21: May | G21: Jun | H21: Jul | I21: Aug | J21: Sep | K21: Oct | L21: Nov | M21: Dec | N21: Total
A22: Year 1 - Seasonality in % | B22: 0.05 | C22: 0.05 | D22: 0.08 | E22: 0.11 | F22: 0.14 | G22: 0.1 | H22: 0.07 | I22: 0.08 | J22: 0.12 | K22: 0.13 | L22: 0.06 | M22: 0.01 | N22: =SUM(B22:M22) -> 1
A23: Year 2 - Seasonality in % | B23: 0.05 | C23: 0.05 | D23: 0.08 | E23: 0.11 | F23: 0.14 | G23: 0.1 | H23: 0.07 | I23: 0.08 | J23: 0.12 | K23: 0.13 | L23: 0.06 | M23: 0.01 | N23: =SUM(B23:M23) -> 1
A26: Sales Projection for 2026
A27: Month | B27: 46047 | C27: 46078 | D27: 46106 | E27: 46137 | F27: 46167 | G27: 46198 | H27: 46228 | I27: 46259 | J27: 46290 | K27: 46320 | L27: 46351 | M27: 46381 | N27: Total
A28: Seasonality Pattern in % | B28: =B22 -> 0.05 | C28: =C22 -> 0.05 | D28: =D22 -> 0.08 | E28: =E22 -> 0.11 | F28: =F22 -> 0.14 | G28: =G22 -> 0.1 | H28: =H22 -> 0.07 | I28: =I22 -> 0.08 | ... M28: =M22 -> 0.01 | N28: =SUM(B28:M28) -> 1
A29: Online Bookings | B29: =$B$4*$B$11*B28 -> 5043 | C29: =$B$4*$B$11*C28 -> 5043 | D29: =$B$4*$B$11*D28 -> 8068.8 | E29: =$B$4*$B$11*E28 -> 11094.6 | F29: =$B$4*$B$11*F28 -> 14120.4 | G29: =$B$4*$B$11*G28 -> 10086 | H29: =$B$4*$B$11*H28 -> 7060.2 | I29: =$B$4*$B$11*I28 -> 8068.8 | ... M29: =$B$4*$B$11*M28 -> 1008.6 | N29: =SUM(B29:M29) -> 100860
A30: Cash | B30: =B29*$B$16 -> 1512.9 | C30: =C29*$B$16 -> 1512.9 | D30: =D29*$B$16 -> 2420.64 | E30: =E29*$B$16 -> 3328.38 | F30: =F29*$B$16 -> 4236.12 | G30: =G29*$B$16 -> 3025.8 | H30: =H29*$B$16 -> 2118.06 | I30: =I29*$B$16 -> 2420.64 | ... M30: =M29*$B$16 -> 302.58 | N30: =SUM(B30:M30) -> 30258
A31: Credit Card | B31: =B29*$C$16 -> 3530.1 | C31: =C29*$C$16 -> 3530.1 | D31: =D29*$C$16 -> 5648.16 | E31: =E29*$C$16 -> 7766.22 | F31: =F29*$C$16 -> 9884.28 | G31: =G29*$C$16 -> 7060.2 | H31: =H29*$C$16 -> 4942.14 | I31: =I29*$C$16 -> 5648.16 | ... M31: =M29*$C$16 -> 706.02 | N31: =SUM(B31:M31) -> 70602
A32: Phone Booking | B32: =$B$4*$B$12*B28 -> 3362 | C32: =$B$4*$B$12*C28 -> 3362 | D32: =$B$4*$B$12*D28 -> 5379.2 | E32: =$B$4*$B$12*E28 -> 7396.4 | F32: =$B$4*$B$12*F28 -> 9413.6 | G32: =$B$4*$B$12*G28 -> 6724 | H32: =$B$4*$B$12*H28 -> 4706.8 | I32: =$B$4*$B$12*I28 -> 5379.2 | ... M32: =$B$4*$B$12*M28 -> 672.4 | N32: =SUM(B32:M32) -> 67240
A33: Cash | B33: =B32*$B$17 -> 2017.2 | C33: =C32*$B$17 -> 2017.2 | D33: =D32*$B$17 -> 3227.52 | E33: =E32*$B$17 -> 4437.84 | F33: =F32*$B$17 -> 5648.16 | G33: =G32*$B$17 -> 4034.4 | H33: =H32*$B$17 -> 2824.08 | I33: =I32*$B$17 -> 3227.52 | ... M33: =M32*$B$17 -> 403.44 | N33: =SUM(B33:M33) -> 40344
A34: Credit Card | B34: =B32*$C$17 -> 1344.8 | C34: =C32*$C$17 -> 1344.8 | D34: =D32*$C$17 -> 2151.68 | E34: =E32*$C$17 -> 2958.56 | F34: =F32*$C$17 -> 3765.44 | G34: =G32*$C$17 -> 2689.6 | H34: =H32*$C$17 -> 1882.72 | I34: =I32*$C$17 -> 2151.68 | ... M34: =M32*$C$17 -> 268.96 | N34: =SUM(B34:M34) -> 26896
A35: Total Year 1 Sales | B35: =B29+B32 -> 8405 | C35: =C29+C32 -> 8405 | D35: =D29+D32 -> 13448 | E35: =E29+E32 -> 18491 | F35: =F29+F32 -> 23534 | G35: =G29+G32 -> 16810 | H35: =H29+H32 -> 11767 | I35: =I29+I32 -> 13448 | ... M35: =M29+M32 -> 1681 | N35: =SUM(B35:M35) -> 168100 | P35: =SUM(N29,N32) -> 168100
A38: Sales Projection for 2027
A39: Month | B39: 46412 | C39: 46443 | D39: 46471 | E39: 46502 | F39: 46532 | G39: 46563 | H39: 46593 | I39: 46624 | J39: 46655 | K39: 46685 | L39: 46716 | M39: 46746 | N39: Total
A40: Seasonality Pattern in % | B40: =B23 -> 0.05 | C40: =C23 -> 0.05 | D40: =D23 -> 0.08 | E40: =E23 -> 0.11 | F40: =F23 -> 0.14 | G40: =G23 -> 0.1 | H40: =H23 -> 0.07 | I40: =I23 -> 0.08 | ... M40: =M23 -> 0.01 | N40: =SUM(B40:M40) -> 1
A41: Online Bookings | B41: =$B$6*$B$11*B40 -> 9329.55 | C41: =$B$6*$B$11*C40 -> 9329.55 | D41: =$B$6*$B$11*D40 -> 14927.28 | E41: =$B$6*$B$11*E40 -> 20525.01 | F41: =$B$6*$B$11*F40 -> 26122.74 | G41: =$B$6*$B$11*G40 -> 18659.1 | H41: =$B$6*$B$11*H40 -> 13061.37 | I41: =$B$6*$B$11*I40 -> 14927.28 | ... M41: =$B$6*$B$11*M40 -> 1865.91 | N41: =SUM(B41:M41) -> 186591
A42: Cash | B42: =B41*$B$16 -> 2798.865 | C42: =C41*$B$16 -> 2798.865 | D42: =D41*$B$16 -> 4478.184 | E42: =E41*$B$16 -> 6157.503 | F42: =F41*$B$16 -> 7836.822 | G42: =G41*$B$16 -> 5597.73 | H42: =H41*$B$16 -> 3918.411 | I42: =I41*$B$16 -> 4478.184 | ... M42: =M41*$B$16 -> 559.773 | N42: =SUM(B42:M42) -> 55977.3
A43: Credit Card | B43: =B41*$C$16 -> 6530.685 | C43: =C41*$C$16 -> 6530.685 | D43: =D41*$C$16 -> 10449.096 | E43: =E41*$C$16 -> 14367.507 | F43: =F41*$C$16 -> 18285.918 | G43: =G41*$C$16 -> 13061.37 | H43: =H41*$C$16 -> 9142.959 | I43: =I41*$C$16 -> 10449.096 | ... M43: =M41*$C$16 -> 1306.137 | N43: =SUM(B43:M43) -> 130613.7
A44: Phone Booking | B44: =$B$6*$B$12*B40 -> 6219.7 | C44: =$B$6*$B$12*C40 -> 6219.7 | D44: =$B$6*$B$12*D40 -> 9951.52 | E44: =$B$6*$B$12*E40 -> 13683.34 | F44: =$B$6*$B$12*F40 -> 17415.16 | G44: =$B$6*$B$12*G40 -> 12439.4 | H44: =$B$6*$B$12*H40 -> 8707.58 | I44: =$B$6*$B$12*I40 -> 9951.52 | ... M44: =$B$6*$B$12*M40 -> 1243.94 | N44: =SUM(B44:M44) -> 124394
A45: Cash | B45: =B44*$B$17 -> 3731.82 | C45: =C44*$B$17 -> 3731.82 | D45: =D44*$B$17 -> 5970.912 | E45: =E44*$B$17 -> 8210.004 | F45: =F44*$B$17 -> 10449.096 | G45: =G44*$B$17 -> 7463.64 | H45: =H44*$B$17 -> 5224.548 | I45: =I44*$B$17 -> 5970.912 | ... M45: =M44*$B$17 -> 746.364 | N45: =SUM(B45:M45) -> 74636.4
A46: Credit Card | B46: =B44*$C$17 -> 2487.88 | C46: =C44*$C$17 -> 2487.88 | D46: =D44*$C$17 -> 3980.608 | E46: =E44*$C$17 -> 5473.336 | F46: =F44*$C$17 -> 6966.064 | G46: =G44*$C$17 -> 4975.76 | H46: =H44*$C$17 -> 3483.032 | I46: =I44*$C$17 -> 3980.608 | ... M46: =M44*$C$17 -> 497.576 | N46: =SUM(B46:M46) -> 49757.6
A47: Total Year 2 Sales | B47: =B41+B44 -> 15549.25 | C47: =C41+C44 -> 15549.25 | D47: =D41+D44 -> 24878.8 | E47: =E41+E44 -> 34208.35 | F47: =F41+F44 -> 43537.9 | G47: =G41+G44 -> 31098.5 | H47: =H41+H44 -> 21768.95 | I47: =I41+I44 -> 24878.8 | ... M47: =M41+M44 -> 3109.85 | N47: =SUM(B47:M47) -> 310985 | P47: =SUM(N41,N44) -> 310985
A51: Notes:
A52: All the values are rounded to a whole number
...

Sheet Marketing
A1: Marketing
A4: Year 1 -Total Rec. Mkt. Spent | B4: =Sales!N35*0.08 -> 13448
A5: Year 2 -Total Rec. Mkt. Spent | B5: =B4*(1+Sales!B5) -> 24878.8
A6: Recurring Monthly Marketing Expense - Year 1
B7: 46048 | C7: 46079 | D7: 46107 | E7: 46138 | F7: 46168 | G7: 46199 | H7: 46229 | I7: 46260 | J7: 46291 | K7: 46321 | L7: 46352 | M7: 46382 | N7: Total
A8: Year 1 - Seasonality in % | B8: =Sales!B35/Sales!$N$35 -> 0.05 | C8: =Sales!C35/Sales!$N$35 -> 0.05 | D8: =Sales!D35/Sales!$N$35 -> 0.08 | E8: =Sales!E35/Sales!$N$35 -> 0.11 | F8: =Sales!F35/Sales!$N$35 -> 0.14 | G8: =Sales!G35/Sales!$N$35 -> 0.1 | H8: =Sales!H35/Sales!$N$35 -> 0.07 | I8: =Sales!I35/Sales!$N$35 -> 0.08 | ... N8: =Sales!N35/Sales!$N$35 -> 1
A9: Paid Social Media Advertising | B9: =($B$4*$B$8)/4 -> 168.1 | C9: =($B$4*$C$8)/4 -> 168.1 | D9: =($B$4*$D$8)/4 -> 268.96 | E9: =($B$4*$E$8)/4 -> 369.82 | F9: =($B$4*$F$8)/4 -> 470.68 | G9: =($B$4*$G$8)/4 -> 336.2 | H9: =($B$4*$H$8)/4 -> 235.34 | I9: =($B$4*$I$8)/4 -> 268.96 | J9: =($B$4*$J$8)/4 -> 403.44 | K9: =($B$4*$K$8)/4 -> 437.06 | L9: =($B$4*$L$8)/4 -> 201.72 | M9: =($B$4*$M$8)/4 -> 33.62 | N9: =SUM(B9:M9) -> 3362
A10: Google Ads | B10: =($B$4*$B$8)/4 -> 168.1 | C10: =($B$4*$C$8)/4 -> 168.1 | D10: =($B$4*$D$8)/4 -> 268.96 | E10: =($B$4*$E$8)/4 -> 369.82 | F10: =($B$4*$F$8)/4 -> 470.68 | G10: =($B$4*$G$8)/4 -> 336.2 | H10: =($B$4*$H$8)/4 -> 235.34 | I10: =($B$4*$I$8)/4 -> 268.96 | J10: =($B$4*$J$8)/4 -> 403.44 | K10: =($B$4*$K$8)/4 -> 437.06 | L10: =($B$4*$L$8)/4 -> 201.72 | M10: =($B$4*$M$8)/4 -> 33.62 | N10: =SUM(B10:M10) -> 3362
A11: Local Print Advertising | B11: =(B4*$B$8)/4 -> 168.1 | C11: =($B$4*$C$8)/4 -> 168.1 | D11: =($B$4*$D$8)/4 -> 268.96 | E11: =($B$4*$E$8)/4 -> 369.82 | F11: =($B$4*$F$8)/4 -> 470.68 | G11: =($B$4*$G$8)/4 -> 336.2 | H11: =($B$4*$H$8)/4 -> 235.34 | I11: =($B$4*$I$8)/4 -> 268.96 | J11: =($B$4*$J$8)/4 -> 403.44 | K11: =($B$4*$K$8)/4 -> 437.06 | L11: =($B$4*$L$8)/4 -> 201.72 | M11: =($B$4*$M$8)/4 -> 33.62 | N11: =SUM(B11:M11) -> 3362
A12: Website Maintenance | B12: =(B4*$B$8)/4 -> 168.1 | C12: =($B$4*$C$8)/4 -> 168.1 | D12: =($B$4*$D$8)/4 -> 268.96 | E12: =($B$4*$E$8)/4 -> 369.82 | F12: =($B$4*$F$8)/4 -> 470.68 | G12: =($B$4*$G$8)/4 -> 336.2 | H12: =($B$4*$H$8)/4 -> 235.34 | I12: =($B$4*$I$8)/4 -> 268.96 | J12: =($B$4*$J$8)/4 -> 403.44 | K12: =($B$4*$K$8)/4 -> 437.06 | L12: =($B$4*$L$8)/4 -> 201.72 | M12: =($B$4*$M$8)/4 -> 33.62 | N12: =SUM(B12:M12) -> 3362
A13: Monthly Total | B13: =SUM(B9:B12) -> 672.4 | C13: =SUM(C9:C12) -> 672.4 | D13: =SUM(D9:D12) -> 1075.84 | E13: =SUM(E9:E12) -> 1479.28 | F13: =SUM(F9:F12) -> 1882.72 | G13: =SUM(G9:G12) -> 1344.8 | H13: =SUM(H9:H12) -> 941.36 | I13: =SUM(I9:I12) -> 1075.84 | ... M13: =SUM(M9:M12) -> 134.48 | N13: =SUM(B13:M13) -> 13448
A15: Recurring Monthly Marketing Expense - Year 1
B16: 46413 | C16: 46444 | D16: 46472 | E16: 46503 | F16: 46533 | G16: 46564 | H16: 46594 | I16: 46625 | J16: 46656 | K16: 46686 | L16: 46717 | M16: 46747 | N16: Total
A17: Year 2 - Seasonality in % | B17: =Sales!B47/Sales!$B$6 -> 0.05 | C17: =Sales!C47/Sales!$B$6 -> 0.05 | D17: =Sales!D47/Sales!$B$6 -> 0.08 | E17: =Sales!E47/Sales!$B$6 -> 0.11 | F17: =Sales!F47/Sales!$B$6 -> 0.14 | G17: =Sales!G47/Sales!$B$6 -> 0.1 | H17: =Sales!H47/Sales!$B$6 -> 0.07 | I17: =Sales!I47/Sales!$B$6 -> 0.08 | ... M17: =Sales!M47/Sales!$B$6 -> 0.01 | N17: =SUM(B17:M17) -> 1
A18: Paid Social Media Advertising | B18: =($B$5*B$17)/4 -> 310.985 | C18: =($B$5*C$17)/4 -> 310.985 | D18: =($B$5*D$17)/4 -> 497.576 | E18: =($B$5*E$17)/4 -> 684.167 | F18: =($B$5*F$17)/4 -> 870.758 | G18: =($B$5*G$17)/4 -> 621.97 | H18: =($B$5*H$17)/4 -> 435.379 | I18: =($B$5*I$17)/4 -> 497.576 | ... M18: =($B$5*M$17)/4 -> 62.197 | N18: =SUM(B18:M18) -> 6219.7
A19: Google Ads | B19: =($B$5*B$17)/4 -> 310.985 | C19: =($B$5*C$17)/4 -> 310.985 | D19: =($B$5*D$17)/4 -> 497.576 | E19: =($B$5*E$17)/4 -> 684.167 | F19: =($B$5*F$17)/4 -> 870.758 | G19: =($B$5*G$17)/4 -> 621.97 | H19: =($B$5*H$17)/4 -> 435.379 | I19: =($B$5*I$17)/4 -> 497.576 | ... M19: =($B$5*M$17)/4 -> 62.197 | N19: =SUM(B19:M19) -> 6219.7
A20: Local Print Advertising | B20: =($B$5*B$17)/4 -> 310.985 | C20: =($B$5*C$17)/4 -> 310.985 | D20: =($B$5*D$17)/4 -> 497.576 | E20: =($B$5*E$17)/4 -> 684.167 | F20: =($B$5*F$17)/4 -> 870.758 | G20: =($B$5*G$17)/4 -> 621.97 | H20: =($B$5*H$17)/4 -> 435.379 | I20: =($B$5*I$17)/4 -> 497.576 | ... M20: =($B$5*M$17)/4 -> 62.197 | N20: =SUM(B20:M20) -> 6219.7
A21: Website Maintenance | B21: =($B$5*B$17)/4 -> 310.985 | C21: =($B$5*C$17)/4 -> 310.985 | D21: =($B$5*D$17)/4 -> 497.576 | E21: =($B$5*E$17)/4 -> 684.167 | F21: =($B$5*F$17)/4 -> 870.758 | G21: =($B$5*G$17)/4 -> 621.97 | H21: =($B$5*H$17)/4 -> 435.379 | I21: =($B$5*I$17)/4 -> 497.576 | ... M21: =($B$5*M$17)/4 -> 62.197 | N21: =SUM(B21:M21) -> 6219.7
A22: Monthly Total | B22: =SUM(B18:B21) -> 1243.94 | C22: =SUM(C18:C21) -> 1243.94 | D22: =SUM(D18:D21) -> 1990.304 | E22: =SUM(E18:E21) -> 2736.668 | F22: =SUM(F18:F21) -> 3483.032 | G22: =SUM(G18:G21) -> 2487.88 | H22: =SUM(H18:H21) -> 1741.516 | I22: =SUM(I18:I21) -> 1990.304 | ... M22: =SUM(M18:M21) -> 248.788 | N22: =SUM(B22:M22) -> 24878.8
A25: One-Time Marketing Expense
A26: Category | B26: One-Time Amount ($)
A27: Logo Design | B27: 750
A28: Vehicle Wrap Design | B28: 3500
A29: Website Development | B29: 3000
A30: Initial Advertising Campaign | B30: 2500
A31: Total | B31: =SUM(B27:B30) -> 9750
A33: Seasonal Marketing Expense
A34: Category | B34: Annual Amount
A35: Event Participation | B35: 5000
A36: Partnership Promotions | B36: 3000
A37: Seasonal Specials | B37: 2400
A38: Total | B38: =SUM(B35:B37) -> 10400
A40: Grand Total of Marketing Expenses for Year 1 | B40: =N13+B31+B38 -> 33598
A43: Notes
A44: Monthly marketing cost is calculated based on seasonality pattern

Sheet Assets
A1: Assets and Depreciation
A3: Description | B3: Cost | C3: useful life (yrs) | D3: Value end | E3: Yearly Depreciation | F3: Notes
A4: Mobile Grooming Van | B4: 40000 | C4: 5 | D4: 5000 | E4: 7000 | F4: Includes the cost of the van used for mobile grooming services.
A5: Van Customization | B5: 15000 | C5: 5 | D5: 0 | E5: 3000 | F5: Interior setup for grooming services (e.g., water tanks, grooming tables).
A6: Grooming Equipment | B6: 5000 | C6: 3 | D6: 0 | E6: 1667 | F6: Includes clippers, dryers, scissors, and other grooming tools.
A7: Office Equipment | B7: 2200 | C7: 4 | D7: 0 | E7: 550 | F7: Computer and printer for administrative tasks.
A8: Total | B8: =SUM(B4:B7) -> 62200 | D8: =SUM(D4:D7) -> 5000 | E8: =SUM(E4:E7) -> 12217
A11: Yearly Depreciation Summary
B12: 2026 | C12: 2027
A13: Original Cost | B13: =B8 -> 62200 | C13: =B13-B14 -> 49983
A14: Accumulated Depreciation | B14: =SUM(E4:E7) -> 12217 | C14: =E8 -> 12217

Sheet HR Exp
A1: Human Resource Expenses
A3: Category | B3: Amount
A4: Owner Draw Per Month | B4: 3000 | C4: Starts from April
A5: Owner Gov't Payroll Tax % | B5: 0
A6: Owner Benefits Per Month | B6: 0
A7: Owner % Production | B7: 0
A9: Category | B9: Amount
A10: Full-Time Groomer
A11: Full Time Hrs Per Month | B11: 160 | C11: Based on 40 hours per week
A12: Full Time Wages Per Hour | B12: 22
A13: Full Time Payroll Tax and Benefits % | B13: 0.21
A14: Part-Time Assistant
A15: Part Time Wage Per Hour | B15: 18
A16: Part Time Payroll Tax and Benefits % | B16: 0.18
A19: Month | B19: 46023 | C19: 46054 | D19: 46082 | E19: 46113 | F19: 46143 | G19: 46174 | H19: 46204 | I19: 46235 | J19: 46266 | K19: 46296 | L19: 46327 | M19: 46357 | N19: TOTAL
A20: Full-Time Hours | B20: 160 | C20: 160 | D20: 160 | E20: 160 | F20: 160 | G20: 160 | H20: 160 | I20: 160 | J20: 160 | K20: 160 | L20: 160 | M20: 160 | N20: =SUM(B20:M20) -> 1920
A21: Full-Time Wages | B21: =B20*$B$12 -> 3520 | C21: =C20*$B$12 -> 3520 | D21: =D20*$B$12 -> 3520 | E21: =E20*$B$12 -> 3520 | F21: =F20*$B$12 -> 3520 | G21: =G20*$B$12 -> 3520 | H21: =H20*$B$12 -> 3520 | I21: =I20*$B$12 -> 3520 | ... N21: =N20*$B$12 -> 42240
A22: Full-Time Benefits | B22: =B21*$B$13 -> 739.2 | C22: =C21*$B$13 -> 739.2 | D22: =D21*$B$13 -> 739.2 | E22: =E21*$B$13 -> 739.2 | F22: =F21*$B$13 -> 739.2 | G22: =G21*$B$13 -> 739.2 | H22: =H21*$B$13 -> 739.2 | I22: =I21*$B$13 -> 739.2 | ... N22: =N21*$B$13 -> 8870.4
A23: Part-Time Hours | B23: 0 | C23: 0 | D23: 0 | E23: 0 | F23: 60 | G23: 60 | H23: 30 | I23: 60 | J23: 90 | K23: 100 | L23: 60 | M23: 0 | N23: =SUM(B23:M23) -> 460
A24: Part-Time Wages | B24: =B23*$B$15 -> 0 | C24: =C23*$B$15 -> 0 | D24: =D23*$B$15 -> 0 | E24: =E23*$B$15 -> 0 | F24: =F23*$B$15 -> 1080 | G24: =G23*$B$15 -> 1080 | H24: =H23*$B$15 -> 540 | I24: =I23*$B$15 -> 1080 | ... N24: =N23*$B$15 -> 8280
A25: Part-Time Benefits | B25: =B24*$B$16 -> 0 | C25: =C24*$B$16 -> 0 | D25: =D24*$B$16 -> 0 | E25: =E24*$B$16 -> 0 | F25: =F24*$B$16 -> 194.4 | G25: =G24*$B$16 -> 194.4 | H25: =H24*$B$16 -> 97.2 | I25: =I24*$B$16 -> 194.4 | ... N25: =N24*$B$16 -> 1490.4
A26: Monthly Total | B26: {=SUM(B21:B22+B24:B25)} -> 4259.2 | C26: {=SUM(C21:C22+C24:C25)} -> 4259.2 | D26: {=SUM(D21:D22+D24:D25)} -> 4259.2 | E26: {=SUM(E21:E22+E24:E25)} -> 4259.2 | F26: {=SUM(F21:F22+F24:F25)} -> 5533.6 | G26: {=SUM(G21:G22+G24:G25)} -> 5533.6 | H26: {=SUM(H21:H22+H24:H25)} -> 4896.4 | I26: {=SUM(I21:I22+I24:I25)} -> 5533.6 | ... N26: {=SUM(N21:N22+N24:N25)} -> 60880.8
A28: Month | B28: 46388 | C28: 46419 | D28: 46447 | E28: 46478 | F28: 46508 | G28: 46539 | H28: 46569 | I28: 46600 | J28: 46631 | K28: 46661 | L28: 46692 | M28: 46722 | N28: TOTAL
A29: Full-Time Hours | B29: 320 | C29: 320 | D29: 320 | E29: 320 | F29: 320 | G29: 320 | H29: 320 | I29: 320 | J29: 320 | K29: 320 | L29: 320 | M29: 320 | N29: =SUM(B29:M29) -> 3840
A30: Full-Time Wages | B30: =B29*$B$12 -> 7040 | C30: =C29*$B$12 -> 7040 | D30: =D29*$B$12 -> 7040 | E30: =E29*$B$12 -> 7040 | F30: =F29*$B$12 -> 7040 | G30: =G29*$B$12 -> 7040 | H30: =H29*$B$12 -> 7040 | I30: =I29*$B$12 -> 7040 | ... N30: =N29*$B$12 -> 84480
A31: Full-Time Benefits | B31: =B30*$B$13 -> 1478.4 | C31: =C30*$B$13 -> 1478.4 | D31: =D30*$B$13 -> 1478.4 | E31: =E30*$B$13 -> 1478.4 | F31: =F30*$B$13 -> 1478.4 | G31: =G30*$B$13 -> 1478.4 | H31: =H30*$B$13 -> 1478.4 | I31: =I30*$B$13 -> 1478.4 | ... N31: =N30*$B$13 -> 17740.8
A32: Part-Time Hours | B32: 0 | C32: 0 | D32: 0 | E32: 0 | F32: 120 | G32: 120 | H32: 60 | I32: 120 | J32: 180 | K32: 200 | L32: 120 | M32: 0 | N32: =SUM(B32:M32) -> 920
A33: Part-Time Wages | B33: =B32*$B$15 -> 0 | C33: =C32*$B$15 -> 0 | D33: =D32*$B$15 -> 0 | E33: =E32*$B$15 -> 0 | F33: =F32*$B$15 -> 2160 | G33: =G32*$B$15 -> 2160 | H33: =H32*$B$15 -> 1080 | I33: =I32*$B$15 -> 2160 | ... N33: =N32*$B$15 -> 16560
A34: Part-Time Benefits | B34: =B33*$B$16 -> 0 | C34: =C33*$B$16 -> 0 | D34: =D33*$B$16 -> 0 | E34: =E33*$B$16 -> 0 | F34: =F33*$B$16 -> 388.8 | G34: =G33*$B$16 -> 388.8 | H34: =H33*$B$16 -> 194.4 | I34: =I33*$B$16 -> 388.8 | ... N34: =N33*$B$16 -> 2980.8
A35: Monthly Total | B35: {=SUM(B30:B31+B33:B34)} -> 8518.4 | C35: {=SUM(C30:C31+C33:C34)} -> 8518.4 | D35: {=SUM(D30:D31+D33:D34)} -> 8518.4 | E35: {=SUM(E30:E31+E33:E34)} -> 8518.4 | F35: {=SUM(F30:F31+F33:F34)} -> 11067.2 | G35: {=SUM(G30:G31+G33:G34)} -> 11067.2 | H35: {=SUM(H30:H31+H33:H34)} -> 9792.8 | I35: {=SUM(I30:I31+I33:I34)} -> 11067.2 | ... N35: {=SUM(N30:N31+N33:N34)} -> 121761.6

Sheet Financing
A1: Financing
A3: Credit Card Fees | B3: 0.0125
A5: Line of Credit Factors
A6: Interest Rate | B6: 0.035
A7: Interest Rate/month | B7: =B6/12 -> 0.0029166667
A8: Credit Limit | B8: 100000
A10: Contingency Amount | B10: 1500
A12: Loan Calculation Worksheet- Parent's Loan
A13: Interest Rate | B13: 0.07
A14: Interest Rate/mth | B14: =B13/12 -> 0.0058333333
A15: Period | B15: =12*5 -> 60
A16: Amount of Loan (PV) | B16: 40000
A17: Final Loan Balance (FV) | B17: 0
A18: Monthly Payment | B18: =-PMT(B14,B15,B16,B17,) -> 792.04794
A20: Loan Payment Table - Parent's Loan | B20: 1 | C20: 2 | D20: 3 | E20: 4 | F20: 5 | G20: 6 | H20: 7 | I20: 8 | J20: 9 | K20: 10 | L20: 11 | M20: 12 | N20: Total
A21: Year 1 | B21: 45658 | C21: 45689 | D21: 45717 | E21: 45748 | F21: 45778 | G21: 45809 | H21: 45839 | I21: 45870 | J21: 45901 | K21: 45931 | L21: 45962 | M21: 45992
A22: Payment Number | C22: 1 | D22: 2 | E22: 3 | F22: 4 | G22: 5 | H22: 6 | I22: 7 | J22: 8 | K22: 9 | L22: 10 | M22: 11
A23: Opening balance | B23: 0 | C23: =B16 -> 40000 | D23: =C27 -> 39441.285 | E23: =D27 -> 38879.312 | F23: =E27 -> 38314.06 | G23: =F27 -> 37745.51 | H23: =G27 -> 37173.645 | I23: =H27 -> 36598.443 | J23: =I27 -> 36019.886 | K23: =J27 -> 35437.954 | ... M23: =L27 -> 34263.886
A24: Payment | B24: 0 | C24: =$B$18 -> 792.04794 | D24: =$B$18 -> 792.04794 | E24: =$B$18 -> 792.04794 | F24: =$B$18 -> 792.04794 | G24: =$B$18 -> 792.04794 | H24: =$B$18 -> 792.04794 | I24: =$B$18 -> 792.04794 | J24: =$B$18 -> 792.04794 | ... M24: =$B$18 -> 792.04794 | N24: =SUM(C24:M24) -> 8712.5274
A25: Interest portion of payment | B25: 0 | C25: =-IPMT($B$14,C22,$B$15,$B$16,$B$17) -> 233.33333 | D25: =-IPMT($B$14,D22,$B$15,$B$16,$B$17) -> 230.07416 | E25: =-IPMT($B$14,E22,$B$15,$B$16,$B$17) -> 226.79598 | F25: =-IPMT($B$14,F22,$B$15,$B$16,$B$17) -> 223.49868 | G25: =-IPMT($B$14,G22,$B$15,$B$16,$B$17) -> 220.18214 | H25: =-IPMT($B$14,H22,$B$15,$B$16,$B$17) -> 216.84626 | I25: =-IPMT($B$14,I22,$B$15,$B$16,$B$17) -> 213.49092 | J25: =-IPMT($B$14,J22,$B$15,$B$16,$B$17) -> 210.116 | ... M25: =-IPMT($B$14,M22,$B$15,$B$16,$B$17) -> 199.87267 | N25: =SUM(C25:M25) -> 2384.2385
A26: Principal portion of payment | B26: 0 | C26: =-PPMT($B$14,C22,$B$15,$B$16,$B$17) -> 558.71461 | D26: =-PPMT($B$14,D22,$B$15,$B$16,$B$17) -> 561.97378 | E26: =-PPMT($B$14,E22,$B$15,$B$16,$B$17) -> 565.25196 | F26: =-PPMT($B$14,F22,$B$15,$B$16,$B$17) -> 568.54926 | G26: =-PPMT($B$14,G22,$B$15,$B$16,$B$17) -> 571.8658 | H26: =-PPMT($B$14,H22,$B$15,$B$16,$B$17) -> 575.20168 | I26: =-PPMT($B$14,I22,$B$15,$B$16,$B$17) -> 578.55702 | J26: =-PPMT($B$14,J22,$B$15,$B$16,$B$17) -> 581.93194 | ... M26: =-PPMT($B$14,M22,$B$15,$B$16,$B$17) -> 592.17527 | N26: =SUM(C26:M26) -> 6328.2888
A27: Closing balance | B27: 0 | C27: =C23-C26 -> 39441.285 | D27: =D23-D26 -> 38879.312 | E27: =E23-E26 -> 38314.06 | F27: =F23-F26 -> 37745.51 | G27: =G23-G26 -> 37173.645 | H27: =H23-H26 -> 36598.443 | I27: =I23-I26 -> 36019.886 | J27: =J23-J26 -> 35437.954 | ... M27: =M23-M26 -> 33671.711
A29: Year 2 | B29: 46048 | C29: 46079 | D29: 46107 | E29: 46138 | F29: 46168 | G29: 46199 | H29: 46229 | I29: 46260 | J29: 46291 | K29: 46321 | L29: 46352 | M29: 46382 | N29: Total
A30: Payment Number | B30: 12 | C30: 13 | D30: 14 | E30: 15 | F30: 16 | G30: 17 | H30: 18 | I30: 19 | J30: 20 | K30: 21 | L30: 22 | M30: 23
A31: Opening balance | B31: =M27 -> 33671.711 | C31: =B35 -> 33076.082 | D31: =C35 -> 32476.977 | E31: =D35 -> 31874.379 | F31: =E35 -> 31268.264 | G31: =F35 -> 30658.615 | H31: =G35 -> 30045.409 | I31: =H35 -> 29428.626 | J31: =I35 -> 28808.245 | ... M31: =L35 -> 26925.304
A32: Payment | B32: =$B$18 -> 792.04794 | C32: =$B$18 -> 792.04794 | D32: =$B$18 -> 792.04794 | E32: =$B$18 -> 792.04794 | F32: =$B$18 -> 792.04794 | G32: =$B$18 -> 792.04794 | H32: =$B$18 -> 792.04794 | I32: =$B$18 -> 792.04794 | ... M32: =$B$18 -> 792.04794 | N32: =SUM(B32:M32) -> 9504.5753
A33: Interest portion of payment | B33: =-IPMT($B$14,B30,$B$15,$B$16,$B$17) -> 196.41832 | C33: =-IPMT($B$14,C30,$B$15,$B$16,$B$17) -> 192.94381 | D33: =-IPMT($B$14,D30,$B$15,$B$16,$B$17) -> 189.44904 | E33: =-IPMT($B$14,E30,$B$15,$B$16,$B$17) -> 185.93387 | F33: =-IPMT($B$14,F30,$B$15,$B$16,$B$17) -> 182.39821 | G33: =-IPMT($B$14,G30,$B$15,$B$16,$B$17) -> 178.84192 | H33: =-IPMT($B$14,H30,$B$15,$B$16,$B$17) -> 175.26488 | I33: =-IPMT($B$14,I30,$B$15,$B$16,$B$17) -> 171.66698 | ... M33: =-IPMT($B$14,M30,$B$15,$B$16,$B$17) -> 157.06427 | N33: =SUM(B33:M33) -> 2123.1844
A34: Principal portion of payment | B34: =-PPMT($B$14,B30,$B$15,$B$16,$B$17) -> 595.62963 | C34: =-PPMT($B$14,C30,$B$15,$B$16,$B$17) -> 599.10413 | D34: =-PPMT($B$14,D30,$B$15,$B$16,$B$17) -> 602.59891 | E34: =-PPMT($B$14,E30,$B$15,$B$16,$B$17) -> 606.11407 | F34: =-PPMT($B$14,F30,$B$15,$B$16,$B$17) -> 609.64973 | G34: =-PPMT($B$14,G30,$B$15,$B$16,$B$17) -> 613.20602 | H34: =-PPMT($B$14,H30,$B$15,$B$16,$B$17) -> 616.78306 | I34: =-PPMT($B$14,I30,$B$15,$B$16,$B$17) -> 620.38096 | ... M34: =-PPMT($B$14,M30,$B$15,$B$16,$B$17) -> 634.98367 | N34: =SUM(B34:M34) -> 7381.3909
A35: Closing balance | B35: =B31-B34 -> 33076.082 | C35: =C31-C34 -> 32476.977 | D35: =D31-D34 -> 31874.379 | E35: =E31-E34 -> 31268.264 | F35: =F31-F34 -> 30658.615 | G35: =G31-G34 -> 30045.409 | H35: =H31-H34 -> 29428.626 | I35: =I31-I34 -> 28808.245 | ... M35: =M31-M34 -> 26290.32
A38: Notes
A39: The financing depicts loan and payments of van

Sheet Other Exp
A1: Other Expenses
A5: Category | B5: 46047 | C5: 46078 | D5: 46106 | E5: 46137 | F5: 46167 | G5: 46198 | H5: 46228 | I5: 46259 | J5: 46290 | K5: 46320 | L5: 46351 | M5: 46381 | N5: Total
A6: Repairs and Maintenance | B6: 325 | C6: 325 | D6: 325 | E6: 325 | F6: 325 | G6: 325 | H6: 325 | I6: 325 | J6: 325 | K6: 325 | L6: 325 | M6: 325 | N6: =SUM(B6:M6) -> 3900
A7: Utilities and Telephone | B7: 350 | C7: 350 | D7: 350 | E7: 350 | F7: 350 | G7: 350 | H7: 350 | I7: 350 | J7: 350 | K7: 350 | L7: 350 | M7: 350 | N7: =SUM(B7:M7) -> 4200
A8: Delivery Fees | B8: 300 | C8: 300 | D8: 300 | E8: 300 | F8: 300 | G8: 300 | H8: 300 | I8: 300 | J8: 300 | K8: 300 | L8: 300 | M8: 300 | N8: =SUM(B8:M8) -> 3600
A9: Bank Charges | B9: 40 | C9: 40 | D9: 40 | E9: 40 | F9: 40 | G9: 40 | H9: 40 | I9: 40 | J9: 40 | K9: 40 | L9: 40 | M9: 40 | N9: =SUM(B9:M9) -> 480
A10: Miscellaneous Expenses | B10: 100 | C10: 100 | D10: 100 | E10: 100 | F10: 100 | G10: 100 | H10: 100 | I10: 100 | J10: 100 | K10: 100 | L10: 100 | M10: 100 | N10: =SUM(B10:M10) -> 1200
A11: Total Monthly Expense | B11: =SUM(B6:B10) -> 1115 | C11: =SUM(C6:C10) -> 1115 | D11: =SUM(D6:D10) -> 1115 | E11: =SUM(E6:E10) -> 1115 | F11: =SUM(F6:F10) -> 1115 | G11: =SUM(G6:G10) -> 1115 | H11: =SUM(H6:H10) -> 1115 | I11: =SUM(I6:I10) -> 1115 | ... M11: =SUM(M6:M10) -> 1115 | N11: =SUM(B11:M11) -> 13380
A14: Category | B14: Amount ($) | C14: Frequency
A15: Lease and Location Expense | B15: 10306 | C15: Annual
A16: Professional Fees | B16: 7600 | C16: Annual
A17: Total | B17: =SUM(B15:B16) -> 17906
A19: Monthly Recurring Total | B19: =N11 -> 13380
A21: Annual Total | B21: =B17 -> 17906

Sheet NAICS%
A1: NAICS% (2023)
B3: Whole industry (reliability) | C3: Bottom quartile (25%) | D3: Lower middle (25%) | E3: Upper middle (25%) | F3: Top quartile (25%) | G3: Percentage of businesses reporting
A4: Number of businesses | B4: 4088
A5: Revenue range:
A6: Low Value ($000) | B6: 30 | C6: 30 | D6: 46 | E6: 78 | F6: 190
A7: High Value ($000) | B7: 5000 | C7: 46 | D7: 78 | E7: 190 | F7: 5000
A9: Revenues and expenses | B9: (percentage of total revenue) - Averages
A10: Total revenue | B10: 100 | C10: 100 | D10: 100 | E10: 100 | F10: 100 | G10: 100
A11: Sales of goods and services | B11: N/A | C11: N/A | D11: N/A | E11: N/A | F11: N/A | G11: N/A
A12: All other revenues | B12: N/A | C12: N/A | D12: N/A | E12: N/A | F12: N/A | G12: N/A
A13: Cost of sales (direct expenses) | B13: 19.2A | C13: 7.8000002 | D13: 9.8999996 | E13: 15.4 | F13: 21.799999 | G13: 54.5
A14: Wages and benefits | B14: 6.8A | C14: 0.30000001 | D14: 0.80000001 | E14: 4.5 | F14: 8.3999996 | G14: 10.2
A15: Purchases, materials and sub-contracts | B15: 12.4A | C15: 7.5 | D15: 9.1999998 | E15: 11 | F15: 13.4 | G15: 53.5
A16: Opening inventory | B16: 0.6A | C16: 0.5 | D16: 0.80000001 | E16: 0.60000002 | F16: 0.60000002 | G16: 6.8000002
A17: Closing inventory | B17: 0.6A | C17: 0.40000001 | D17: 0.89999998 | E17: 0.80000001 | F17: 0.60000002 | G17: 6.8000002
A18: Operating expenses (indirect expenses) | B18: 63.6A | C18: 41.400002 | D18: 47.599998 | E18: 58.799999 | F18: 67.800003 | G18: 97.800003
A19: Labour and commissions | B19: 29.3A | C19: 2.5 | D19: 7.5 | E19: 20.200001 | F19: 35.5 | G19: 41.900002
A20: Amortization and depletion | B20: 3.1A | C20: 3 | D20: 3 | E20: 2.9000001 | F20: 3.0999999 | G20: 65.5
A21: Repairs and maintenance | B21: 2.1A | C21: 1.6 | D21: 1.9 | E21: 2.0999999 | F21: 2.0999999 | G21: 60.599998
A22: Utilities and telephone/telecommunication | B22: 2.6A | C22: 3.0999999 | D22: 3.0999999 | E22: 3.2 | F22: 2.4000001 | G22: 81.900002
A23: Rent | B23: 7.5A | C23: 8.3999996 | D23: 8 | E23: 8.8000002 | F23: 7.0999999 | G23: 55.700001
A24: Interest and bank charges | B24: 1.1A | C24: 0.69999999 | D24: 0.89999998 | E24: 1.2 | F24: 1.1 | G24: 45.200001
... A31: Net profit/loss | B31: 17.2A | C31: 50.799999 | D31: 42.5 | E31: 25.799999 | F31: 10.3 | G31: 100
A34: Financial ratios | B34: Averages
A35: Interest coverage ratio | B35: 16.799999 | C35: 77.900002 | D35: 46.400002 | E35: 22.5 | F35: 10.3
A36: Gross margin (%) | B36: 80.800003 | C36: 92.199997 | D36: 90.099998 | E36: 84.599998 | F36: 78.199997
A38: Profitable vs Non-profitable businesses | B38: (thousands of dollars)
A39: Profitable
A40: Percentage of businesses (%) | B40: 83.800003 | C40: N/A | D40: N/A | E40: N/A | F40: N/A
A41: Total revenue | B41: 178.9A | C41: 37.400002 | D41: 59.599998 | E41: 120.6 | F41: 567.5
A42: Total expenses | B42: 129.6A | C42: 15.7 | D42: 27.799999 | E42: 75.5 | F42: 457.5
A43: Net profit | B43: 49.3A | C43: 21.700001 | D43: 31.799999 | E43: 45.099998 | F43: 109.9
A44: Non-Profitable
A45: Percentage of businesses (%) | B45: 16.200001 | C45: N/A | D45: N/A | E45: N/A | F45: N/A
A46: Total revenue | B46: 267.2A | C46: 37.5 | D46: 59.700001 | E46: 128 | F46: 516
A47: Total expenses | B47: 316.8A | C47: 50.200001 | D47: 92.900002 | E47: 150.89999 | F47: 602.40002
A48: Net loss | B48: -49.6A | C48: -12.6 | D48: -33.200001 | E48: -22.9 | F48: -86.400002
A50: Note: Balance sheet information is not available for all businesses and unincorporated businesses under the incorporation status.
A52: Profile
A53: Revenue range | B53: Annual revenues $30,000 - $5,000,000
...

Sheet NAICS$
A1: NAICS$ (2023)
B4: Whole industry (reliability) | C4: Bottom quartile (25%) | D4: Lower middle (25%) | E4: Upper middle (25%) | F4: Top quartile (25%) | G4: Percentage of businesses reporting
A5: Number of businesses | B5: 4088
A6: Revenue range:
A7: Low Value ($000) | B7: 30 | C7: 30 | D7: 46 | E7: 78 | F7: 190
A8: High Value ($000) | B8: 5000 | C8: 46 | D8: 78 | E8: 190 | F8: 5000
A10: Revenues and expenses | B10: (thousands of dollars) - Averages
A11: Total revenue | B11: 193.2A | C11: 37.400002 | D11: 59.599998 | E11: 122.1 | F11: 553.70001 | G11: 100
A12: Sales of goods and services | B12: N/A | C12: N/A | D12: N/A | E12: N/A | F12: N/A | G12: N/A
A13: All other revenues | B13: N/A | C13: N/A | D13: N/A | E13: N/A | F13: N/A | G13: N/A
A14: Cost of sales (direct expenses) | B14: 37.1A | C14: 2.9000001 | D14: 5.9000001 | E14: 18.799999 | F14: 120.8 | G14: 54.5
A15: Wages and benefits | B15: 13.1A | C15: 0.1 | D15: 0.5 | E15: 5.5 | F15: 46.5 | G15: 10.2
A16: Purchases, materials and sub-contracts | B16: 24.0A | C16: 2.8 | D16: 5.5 | E16: 13.5 | F16: 74.099998 | G16: 53.5
A17: Opening inventory | B17: 1.2A | C17: 0.2 | D17: 0.5 | E17: 0.80000001 | F17: 3.3 | G17: 6.8000002
A18: Closing inventory | B18: 1.2A | C18: 0.2 | D18: 0.5 | E18: 1 | F18: 3.0999999 | G18: 6.8000002
A19: Operating expenses (indirect expenses) | B19: 122.8A | C19: 15.5 | D19: 28.299999 | E19: 71.800003 | F19: 375.60001 | G19: 97.800003
A20: Labour and commissions | B20: 56.7A | C20: 1 | D20: 4.5 | E20: 24.6 | F20: 196.60001 | G20: 41.900002
A21: Amortization and depletion | B21: 5.9A | C21: 1.1 | D21: 1.8 | E21: 3.5 | F21: 17.200001 | G21: 65.5
A22: Repairs and maintenance | B22: 4.0A | C22: 0.60000002 | D22: 1.1 | E22: 2.5999999 | F22: 11.7 | G22: 60.599998
A23: Utilities and telephone/telecommunication | B23: 5.0A | C23: 1.2 | D23: 1.8 | E23: 3.9000001 | F23: 13.2 | G23: 81.900002
A24: Rent | B24: 14.5A | C24: 3.0999999 | D24: 4.8000002 | E24: 10.8 | F24: 39.299999 | G24: 55.700001
A25: Interest and bank charges | B25: 2.1A | C25: 0.2 | D25: 0.60000002 | E25: 1.5 | F25: 6.1999998 | G25: 45.200001
... A32: Net profit/loss | B32: 33.3A | C32: 19 | D32: 25.299999 | E32: 31.6 | F32: 57.299999 | G32: 100
A35: Financial ratios | B35: Averages
A36: Interest coverage ratio | B36: 16.799999 | C36: 77.900002 | D36: 46.400002 | E36: 22.5 | F36: 10.3
A37: Gross margin (%) | B37: 80.800003 | C37: 92.199997 | D37: 90.099998 | E37: 84.599998 | F37: 78.199997
A39: Profitable vs Non-profitable businesses | B39: (thousands of dollars)
A40: Profitable
A41: Percentage of businesses (%) | B41: 83.800003 | C41: N/A | D41: N/A | E41: N/A | F41: N/A
A42: Total revenue | B42: 178.9A | C42: 37.400002 | D42: 59.599998 | E42: 120.6 | F42: 567.5
A43: Total expenses | B43: 129.6A | C43: 15.7 | D43: 27.799999 | E43: 75.5 | F43: 457.5
A44: Net profit | B44: 49.3A | C44: 21.700001 | D44: 31.799999 | E44: 45.099998 | F44: 109.9
A45: Non-Profitable
A46: Percentage of businesses (%) | B46: 16.200001 | C46: N/A | D46: N/A | E46: N/A | F46: N/A
A47: Total revenue | B47: 267.2A | C47: 37.5 | D47: 59.700001 | E47: 128 | F47: 516
A48: Total expenses | B48: 316.8A | C48: 50.200001 | D48: 92.900002 | E48: 150.89999 | F48: 602.40002
A49: Net loss | B49: -49.6A | C49: -12.6 | D49: -33.200001 | E49: -22.9 | F49: -86.400002
A51: Note: Balance sheet information is not available for all businesses and unincorporated businesses under the incorporation status.
A53: Profile
A54: Revenue range | B54: Annual revenues $30,000 - $5,000,000
...
